Workbook

Sheet Previsto x realizado
A1: Pilar | B1: Ações | C1: Distribuidora | D1: Regional | E1: Ação Iniciada? | F1: Apuração | G1: Status das ações | H1: Grau de prioridade | I1: Cálculo para meta da distribuidora | J1: Observação da meta da distribuidora | K1: Acumulativo por periodo | L1: Descrição Indicador / Item de controle | M1: Meta | N1: Indicador / Item de controle | O1: Unidade | P1: Indicador de Planejamento | Q1: Indicador de meta de Segurança | R1: Indicadores de resultado descrição | S1: Indicadores de resultado | T1: 46023 | U1: 46054 | V1: 46082 | W1: 46113 | X1: 46143 | Y1: 46174 | Z1: 46204 | AA1: 46235 | AB1: 46266 | AC1: 46296 | AD1: 46327 | AE1: 46357 | AG1: 46023 | AH1: 46054 | AI1: 46082 | AJ1: 46113 | AK1: 46143 | AL1: 46174 | AM1: 46204 | AN1: 46235 | AO1: 46266 | AP1: 46296 | AQ1: 46327 | AR1: 46357 | AS1: Acumulado Prev | AT1: Acumulado Real (Limitado) | AU1: Acumulado Real (Sem limite) | AW1: 46023 | AX1: 46054 | AY1: 46082 | AZ1: 46113 | BA1: 46143 | BB1: 46174 | BC1: 46204 | BD1: 46235 | BE1: 46266 | BF1: 46296 | BG1: 46327 | BH1: 46357 | BI1: Valor do último mês | BJ1: Valor do mês anterior | BK1: Valor acumulado 2026 | BL1: Valor acumulado 2026 (mês antes) | BM1: Mês anterior | BN1: Último mês | BO1: Previsão | BP1: Previsão mês anterior | BQ1: % Recuperação | BR1: Valor Recuperação | BS1: Previsão mês próximo
A2: POPULAÇÃO | B2: Aumenta efetividade de ações técnicas | C2: AL | D2: TODAS | E2: {=_xlfn.IFS( F2 = "A partir de Abril", "Aguardando Execução na Distribuidora", A2 = "CAPACITAÇÃO", "Em execução no Corporativo", TRUE, "Em Execução na Distribuidora" )} -> Em Execução na Distribuidora | F2: {=_xlfn.IFS( AG2 <> "", "Jan-Dez/26", AH2 <> "", "Fev-Dez/26", AI2 <> "", "Mar-Dez/26", AJ2 <> "", "Abr-Dez/26", TRUE, "A partir de Junho" )} -> Jan-Dez/26 | G2: Iniciada | H2: P1 | I2: (N° de soluções implementadas/n° soluções programadas)*100 | J2: {=_xlfn.LET( _xlpm.actual_value_month, INDEX(T2:AE2, MATCH(DATE(YEAR(TODAY()), MONTH(TODAY()), 1), $T$1:$AE$1, 0)), IF(_xlpm.actual_value_month <> "",_xlpm.actual_value_month & " soluções mensais", "") )} -> 2 soluções mensais | K2: {=_xlfn.LET( _xlpm.sum_month, SUM(T2:AE2), IF(_xlpm.sum_month = 0, "", _xlpm.sum_month & " soluções implementadas no ano") )} -> 33 soluções implementadas no ano | L2: Quantidade de soluções implementadas​ | M2: 01 solução implementada por regional por distribuidora | N2: Indicador | O2: Percentual | P2: - | Q2: - | R2: Índice de Compromisso com a Cultura de Segurança (ICCS) | S2: Indicadores de impacto e compromisso em segurança | T2: 5 | U2: 5 | V2: 5 | W2: 2 | X2: 2 | Y2: 2 | Z2: 2 | AA2: 2 | AB2: 2 | AC2: 2 | AD2: 2 | AE2: 2 | AG2: 5 | AH2: 5 | AI2: 5 | AJ2: 3 | AS2: =IF(MONTH(TODAY())=3,SUM(T2:U2),IF(MONTH(TODAY())=4,SUM(T2:V2),IF(MONTH(TODAY())=5,SUM(T2:W2),IF(MONTH(TODAY())=6,SUM(T2:X2),IF(MONTH(TODAY())=7,SUM(T2:Y2),IF(MONTH(TODAY())=8,SUM(T2:Z2),IF(MONTH(TODAY())=9,SUM(T2:AA2),IF(MONTH(TODAY())=10,SUM(T2:AB2),IF(MONTH(TODAY())=11,SUM(T2:AC2),IF(MONTH(TODAY())=12,SUM(T2:AD2),IF(MONTH(TODAY())=1,SUM(T2:AE2),T2))))))))))) -> 19 | AT2: =SUM(IF(AW2<1.15,AG2,1.15*T2),IF(AX2<1.15,AH2,1.15*U2),IF(AY2<1.15,AI2,1.15*V2),IF(AZ2<1.15,AJ2,1.15*W2),IF(BA2<1.15,AK2,1.15*X2),IF(BB2<1.15,AL2,1.15*Y2),IF(BC2<1.15,AM2,1.15*Z2),IF(BD2<1.15,AN2,1.15*AA2),IF(BE2<1.15,AO2,1.15*AB2),IF(BF2<1.15,AP2,1.15*AC2),IF(BG2<1.15,AQ2,1.15*AD2),IF(BH2<1.15,AR2,1.15*AE2)) -> 17.3 | AU2: =SUM(AG2:AR2) -> 18 | AW2: =IFERROR(IF(AG2="",0,AG2/T2),0) -> 1 | AX2: =IFERROR(IF(AH2="",0,AH2/U2),0) -> 1 | AY2: =IFERROR(IF(AI2="",0,AI2/V2),0) -> 1 | AZ2: =IFERROR(IF(AJ2="",0,AJ2/W2),0) -> 1.5 | BI2: {=IFERROR(INDEX(AW2:BH2,1,MATCH(2,1/(AW2:BH2<>""))),"")} -> 1.5 | BJ2: {=IF(BM2 = "", "",IFERROR(INDEX(AW2:BH2,1,MATCH(2,1/(AW2:BH2<>""),1)-1),""))} -> 1 | BK2: =IF((IF(AW2>=115%,115%,AW2) + IF(AX2>=115%,115%,AX2) + IF(AY2>=115%,115%,AY2) + (IF(AZ2>=115%,115%,AZ2) + IF(BA2>=115%,115%,BA2) + IF(BB2>=115%,115%,BB2) + IF(BC2>=115%,115%,BC2) + IF(BD2>=115%,115%,BD2) + IF(BE2>=115%,115%,BE2) + IF(BF2>=115%,115%,BF2) + IF(BG2>=115%,115%,BG2) + IF(BH2>=115%,115%,BH2)))/_xlfn.XLOOKUP(F2,Apuração!A:A,Apuração!B:B)>=1.15,1.15,((IF(AZ2>=115%,115%,AZ2) + IF(AX2>=115%,115%,AX2) + IF(AY2>=115%,115%,AY2) + (IF(AW2>=115%,115%,AW2) + IF(BA2>=115%,115%,BA2) + IF(BB2>=115%,115%,BB2) + IF(BC2>=115%,115%,BC2) + IF(BD2>=115%,115%,BD2) + IF(BE2>=115%,115%,BE2) + IF(BF2>=115%,115%,BF2) + IF(BG2>=115%,115%,BG2) + IF(BH2>=115%,115%,BH2)))/_xlfn.XLOOKUP(F2,Apuração!A:A,Apuração!B:B))) -> 0.34583333 | BL2: {=IF(SUM(IFERROR(IF(INDEX(AW2:INDEX(AW2:BH2, MATCH(2, 1/(AW2:BH2<>""), 1)-1), ROW(INDIRECT("1:" & MATCH(2, 1/(AW2:BH2<>""), 1)-1))) >= 115%, 115%, INDEX(AW2:INDEX(AW2:BH2, MATCH(2, 1/(AW2:BH2<>""), 1)-1), ROW(INDIRECT("1:" & MATCH(2, 1/(AW2:BH2<>""), 1)-1)))), 0))/_xlfn.XLOOKUP(F2,Apuração!A:A,Apuração!B:B)>=1.15,1.15,SUM(IFERROR(IF(INDEX(AW2:INDEX(AW2:BH2, MATCH(2, 1/(AW2:BH2<>""), 1)-1), ROW(INDIRECT("1:" & MATCH(2, 1/(AW2:BH2<>""), 1)-1))) >= 115%, 115%, INDEX(AW2:INDEX(AW2:BH2, MATCH(2, 1/(AW2:BH2<>""), 1)-1), ROW(INDIRECT("1:" & MATCH(2, 1/(AW2:BH2<>""), 1)-1)))), 0))/_xlfn.XLOOKUP(F2,Apuração!A:A,Apuração!B:B))} -> 0.25 | BM2: {=IFERROR( INDEX($AW$1:$BH$1, _xlfn.AGGREGATE(14, 6, COLUMN($AW$1:$BH$1)/(AW2:BH2<>""), 2) - COLUMN($AW$1) + 1 ), "")} -> 46082 | BN2: {=IFERROR(INDEX($AW$1:$BH$1,1,MATCH(2,1/(AW2:BH2<>""))),"")} -> 46113 | BO2: =IFERROR(_xlfn.XLOOKUP(F2,Apuração!A:A,Apuração!C:C)/_xlfn.XLOOKUP(F2,Apuração!A:A,Apuração!B:B),0) -> 0.41666667 | BP2: =IFERROR(_xlfn.XLOOKUP(F2,Apuração!A:A,Apuração!D:D)/_xlfn.XLOOKUP(F2,Apuração!A:A,Apuração!B:B),0) -> 0.33333333 | BQ2: =IF(BK2>=BO2,0,_xlfn.XLOOKUP(F2,Apuração!A:A,Apuração!B:B)*(BO2 + (1/_xlfn.XLOOKUP(F2,Apuração!A:A,Apuração!B:B)) - BK2)) -> 1.85 | BR2: =IF(BQ2=0,0,BQ2*Z2) -> 3.7 | BS2: =IFERROR((_xlfn.XLOOKUP(F2,Apuração!A:A,Apuração!C:C)+1)/_xlfn.XLOOKUP(F2,Apuração!A:A,Apuração!B:B),0) -> 0.5
A3: POPULAÇÃO | B3: Aumenta efetividade de ações técnicas | C3: AL | D3: LESTE | E3: {=_xlfn.IFS( F3 = "A partir de Abril", "Aguardando Execução na Distribuidora", A3 = "CAPACITAÇÃO", "Em execução no Corporativo", TRUE, "Em Execução na Distribuidora" )} -> Em Execução na Distribuidora | F3: {=_xlfn.IFS( AG3 <> "", "Jan-Dez/26", AH3 <> "", "Fev-Dez/26", AI3 <> "", "Mar-Dez/26", AJ3 <> "", "Abr-Dez/26", TRUE, "A partir de Junho" )} -> Fev-Dez/26 | G3: Iniciada | H3: P1 | I3: (N° de soluções implementadas/n° soluções programadas)*100 | J3: {=_xlfn.LET( _xlpm.actual_value_month, INDEX(T3:AE3, MATCH(DATE(YEAR(TODAY()), MONTH(TODAY()), 1), $T$1:$AE$1, 0)), IF(_xlpm.actual_value_month <> "",_xlpm.actual_value_month & " soluções mensais", "") )} -> 1 soluções mensais | K3: {=_xlfn.LET( _xlpm.sum_month, SUM(T3:AE3), IF(_xlpm.sum_month = 0, "", _xlpm.sum_month & " soluções implementadas no ano") )} -> 10 soluções implementadas no ano | L3: Quantidade de soluções implementadas​ | M3: 01 solução implementada por regional por distribuidora | N3: Indicador | O3: Percentual | P3: - | Q3: - | R3: Índice de Compromisso com a Cultura de Segurança (ICCS) | S3: Indicadores de impacto e compromisso em segurança | U3: 1 | W3: 1 | X3: 1 | Y3: 1 | Z3: 1 | AA3: 1 | AB3: 1 | AC3: 1 | AD3: 1 | AE3: 1 | AH3: 1 | AJ3: 0 | AS3: =IF(MONTH(TODAY())=3,SUM(T3:U3),IF(MONTH(TODAY())=4,SUM(T3:V3),IF(MONTH(TODAY())=5,SUM(T3:W3),IF(MONTH(TODAY())=6,SUM(T3:X3),IF(MONTH(TODAY())=7,SUM(T3:Y3),IF(MONTH(TODAY())=8,SUM(T3:Z3),IF(MONTH(TODAY())=9,SUM(T3:AA3),IF(MONTH(TODAY())=10,SUM(T3:AB3),IF(MONTH(TODAY())=11,SUM(T3:AC3),IF(MONTH(TODAY())=12,SUM(T3:AD3),IF(MONTH(TODAY())=1,SUM(T3:AE3),T3))))))))))) -> 3 | AT3: =SUM(IF(AW3<1.15,AG3,1.15*T3),IF(AX3<1.15,AH3,1.15*U3),IF(AY3<1.15,AI3,1.15*V3),IF(AZ3<1.15,AJ3,1.15*W3),IF(BA3<1.15,AK3,1.15*X3),IF(BB3<1.15,AL3,1.15*Y3),IF(BC3<1.15,AM3,1.15*Z3),IF(BD3<1.15,AN3,1.15*AA3),IF(BE3<1.15,AO3,1.15*AB3),IF(BF3<1.15,AP3,1.15*AC3),IF(BG3<1.15,AQ3,1.15*AD3),IF(BH3<1.15,AR3,1.15*AE3)) -> 1 | AU3: =SUM(AG3:AR3) -> 1 | AW3: =IFERROR(IF(AG3="",0,AG3/T3),0) -> 0 | AX3: =IFERROR(IF(AH3="",0,AH3/U3),0) -> 1 | AY3: =IFERROR(IF(AI3="",0,AI3/V3),0) -> 0 | AZ3: =IFERROR(IF(AJ3="",0,AJ3/W3),0) -> 0 | BI3: {=IFERROR(INDEX(AW3:BH3,1,MATCH(2,1/(AW3:BH3<>""))),"")} -> 0 | BJ3: {=IF(BM3 = "", "",IFERROR(INDEX(AW3:BH3,1,MATCH(2,1/(AW3:BH3<>""),1)-1),""))} -> 0 | BK3: =IF((IF(AW3>=115%,115%,AW3) + IF(AX3>=115%,115%,AX3) + IF(AY3>=115%,115%,AY3) + (IF(AZ3>=115%,115%,AZ3) + IF(BA3>=115%,115%,BA3) + IF(BB3>=115%,115%,BB3) + IF(BC3>=115%,115%,BC3) + IF(BD3>=115%,115%,BD3) + IF(BE3>=115%,115%,BE3) + IF(BF3>=115%,115%,BF3) + IF(BG3>=115%,115%,BG3) + IF(BH3>=115%,115%,BH3)))/_xlfn.XLOOKUP(F3,Apuração!A:A,Apuração!B:B)>=1.15,1.15,((IF(AZ3>=115%,115%,AZ3) + IF(AX3>=115%,115%,AX3) + IF(AY3>=115%,115%,AY3) + (IF(AW3>=115%,115%,AW3) + IF(BA3>=115%,115%,BA3) + IF(BB3>=115%,115%,BB3) + IF(BC3>=115%,115%,BC3) + IF(BD3>=115%,115%,BD3) + IF(BE3>=115%,115%,BE3) + IF(BF3>=115%,115%,BF3) + IF(BG3>=115%,115%,BG3) + IF(BH3>=115%,115%,BH3)))/_xlfn.XLOOKUP(F3,Apuração!A:A,Apuração!B:B))) -> 0.090909091 | BL3: {=IF(SUM(IFERROR(IF(INDEX(AW3:INDEX(AW3:BH3, MATCH(2, 1/(AW3:BH3<>""), 1)-1), ROW(INDIRECT("1:" & MATCH(2, 1/(AW3:BH3<>""), 1)-1))) >= 115%, 115%, INDEX(AW3:INDEX(AW3:BH3, MATCH(2, 1/(AW3:BH3<>""), 1)-1), ROW(INDIRECT("1:" & MATCH(2, 1/(AW3:BH3<>""), 1)-1)))), 0))/_xlfn.XLOOKUP(F3,Apuração!A:A,Apuração!B:B)>=1.15,1.15,SUM(IFERROR(IF(INDEX(AW3:INDEX(AW3:BH3, MATCH(2, 1/(AW3:BH3<>""), 1)-1), ROW(INDIRECT("1:" & MATCH(2, 1/(AW3:BH3<>""), 1)-1))) >= 115%, 115%, INDEX(AW3:INDEX(AW3:BH3, MATCH(2, 1/(AW3:BH3<>""), 1)-1), ROW(INDIRECT("1:" & MATCH(2, 1/(AW3:BH3<>""), 1)-1)))), 0))/_xlfn.XLOOKUP(F3,Apuração!A:A,Apuração!B:B))} -> 0.090909091 | BM3: {=IFERROR( INDEX($AW$1:$BH$1, _xlfn.AGGREGATE(14, 6, COLUMN($AW$1:$BH$1)/(AW3:BH3<>""), 2) - COLUMN($AW$1) + 1 ), "")} -> 46082 | BN3: {=IFERROR(INDEX($AW$1:$BH$1,1,MATCH(2,1/(AW3:BH3<>""))),"")} -> 46113 | BO3: =IFERROR(_xlfn.XLOOKUP(F3,Apuração!A:A,Apuração!C:C)/_xlfn.XLOOKUP(F3,Apuração!A:A,Apuração!B:B),0) -> 0.36363636 | BP3: =IFERROR(_xlfn.XLOOKUP(F3,Apuração!A:A,Apuração!D:D)/_xlfn.XLOOKUP(F3,Apuração!A:A,Apuração!B:B),0) -> 0.27272727 | BQ3: =IF(BK3>=BO3,0,_xlfn.XLOOKUP(F3,Apuração!A:A,Apuração!B:B)*(BO3 + (1/_xlfn.XLOOKUP(F3,Apuração!A:A,Apuração!B:B)) - BK3)) -> 4 | BR3: =IF(BQ3=0,0,BQ3*Z3) -> 4 | BS3: =IFERROR((_xlfn.XLOOKUP(F3,Apuração!A:A,Apuração!C:C)+1)/_xlfn.XLOOKUP(F3,Apuração!A:A,Apuração!B:B),0) -> 0.45454545
A4: POPULAÇÃO | B4: Aumenta efetividade de ações técnicas | C4: AL | D4: OESTE | E4: {=_xlfn.IFS( F4 = "A partir de Abril", "Aguardando Execução na Distribuidora", A4 = "CAPACITAÇÃO", "Em execução no Corporativo", TRUE, "Em Execução na Distribuidora" )} -> Em Execução na Distribuidora | F4: {=_xlfn.IFS( AG4 <> "", "Jan-Dez/26", AH4 <> "", "Fev-Dez/26", AI4 <> "", "Mar-Dez/26", AJ4 <> "", "Abr-Dez/26", TRUE, "A partir de Junho" )} -> Jan-Dez/26 | G4: Iniciada | H4: P1 | I4: (N° de soluções implementadas/n° soluções programadas)*100 | J4: {=_xlfn.LET( _xlpm.actual_value_month, INDEX(T4:AE4, MATCH(DATE(YEAR(TODAY()), MONTH(TODAY()), 1), $T$1:$AE$1, 0)), IF(_xlpm.actual_value_month <> "",_xlpm.actual_value_month & " soluções mensais", "") )} -> 1 soluções mensais | K4: {=_xlfn.LET( _xlpm.sum_month, SUM(T4:AE4), IF(_xlpm.sum_month = 0, "", _xlpm.sum_month & " soluções implementadas no ano") )} -> 23 soluções implementadas no ano | L4: Quantidade de soluções implementadas​ | M4: 01 solução implementada por regional por distribuidora | N4: Indicador | O4: Percentual | P4: - | Q4: - | R4: Índice de Compromisso com a Cultura de Segurança (ICCS) | S4: Indicadores de impacto e compromisso em segurança | T4: 5 | U4: 4 | V4: 5 | W4: 1 | X4: 1 | Y4: 1 | Z4: 1 | AA4: 1 | AB4: 1 | AC4: 1 | AD4: 1 | AE4: 1 | AG4: 5 | AH4: 4 | AI4: 5 | AJ4: 3 | AS4: =IF(MONTH(TODAY())=3,SUM(T4:U4),IF(MONTH(TODAY())=4,SUM(T4:V4),IF(MONTH(TODAY())=5,SUM(T4:W4),IF(MONTH(TODAY())=6,SUM(T4:X4),IF(MONTH(TODAY())=7,SUM(T4:Y4),IF(MONTH(TODAY())=8,SUM(T4:Z4),IF(MONTH(TODAY())=9,SUM(T4:AA4),IF(MONTH(TODAY())=10,SUM(T4:AB4),IF(MONTH(TODAY())=11,SUM(T4:AC4),IF(MONTH(TODAY())=12,SUM(T4:AD4),IF(MONTH(TODAY())=1,SUM(T4:AE4),T4))))))))))) -> 16 | AT4: =SUM(IF(AW4<1.15,AG4,1.15*T4),IF(AX4<1.15,AH4,1.15*U4),IF(AY4<1.15,AI4,1.15*V4),IF(AZ4<1.15,AJ4,1.15*W4),IF(BA4<1.15,AK4,1.15*X4),IF(BB4<1.15,AL4,1.15*Y4),IF(BC4<1.15,AM4,1.15*Z4),IF(BD4<1.15,AN4,1.15*AA4),IF(BE4<1.15,AO4,1.15*AB4),IF(BF4<1.15,AP4,1.15*AC4),IF(BG4<1.15,AQ4,1.15*AD4),IF(BH4<1.15,AR4,1.15*AE4)) -> 15.15 | AU4: =SUM(AG4:AR4) -> 17 | AW4: =IFERROR(IF(AG4="",0,AG4/T4),0) -> 1 | AX4: =IFERROR(IF(AH4="",0,AH4/U4),0) -> 1 | AY4: =IFERROR(IF(AI4="",0,AI4/V4),0) -> 1 | AZ4: =IFERROR(IF(AJ4="",0,AJ4/W4),0) -> 3 | BI4: {=IFERROR(INDEX(AW4:BH4,1,MATCH(2,1/(AW4:BH4<>""))),"")} -> 3 | BJ4: {=IF(BM4 = "", "",IFERROR(INDEX(AW4:BH4,1,MATCH(2,1/(AW4:BH4<>""),1)-1),""))} -> 1 | BK4: =IF((IF(AW4>=115%,115%,AW4) + IF(AX4>=115%,115%,AX4) + IF(AY4>=115%,115%,AY4) + (IF(AZ4>=115%,115%,AZ4) + IF(BA4>=115%,115%,BA4) + IF(BB4>=115%,115%,BB4) + IF(BC4>=115%,115%,BC4) + IF(BD4>=115%,115%,BD4) + IF(BE4>=115%,115%,BE4) + IF(BF4>=115%,115%,BF4) + IF(BG4>=115%,115%,BG4) + IF(BH4>=115%,115%,BH4)))/_xlfn.XLOOKUP(F4,Apuração!A:A,Apuração!B:B)>=1.15,1.15,((IF(AZ4>=115%,115%,AZ4) + IF(AX4>=115%,115%,AX4) + IF(AY4>=115%,115%,AY4) + (IF(AW4>=115%,115%,AW4) + IF(BA4>=115%,115%,BA4) + IF(BB4>=115%,115%,BB4) + IF(BC4>=115%,115%,BC4) + IF(BD4>=115%,115%,BD4) + IF(BE4>=115%,115%,BE4) + IF(BF4>=115%,115%,BF4) + IF(BG4>=115%,115%,BG4) + IF(BH4>=115%,115%,BH4)))/_xlfn.XLOOKUP(F4,Apuração!A:A,Apuração!B:B))) -> 0.34583333 | BL4: {=IF(SUM(IFERROR(IF(INDEX(AW4:INDEX(AW4:BH4, MATCH(2, 1/(AW4:BH4<>""), 1)-1), ROW(INDIRECT("1:" & MATCH(2, 1/(AW4:BH4<>""), 1)-1))) >= 115%, 115%, INDEX(AW4:INDEX(AW4:BH4, MATCH(2, 1/(AW4:BH4<>""), 1)-1), ROW(INDIRECT("1:" & MATCH(2, 1/(AW4:BH4<>""), 1)-1)))), 0))/_xlfn.XLOOKUP(F4,Apuração!A:A,Apuração!B:B)>=1.15,1.15,SUM(IFERROR(IF(INDEX(AW4:INDEX(AW4:BH4, MATCH(2, 1/(AW4:BH4<>""), 1)-1), ROW(INDIRECT("1:" & MATCH(2, 1/(AW4:BH4<>""), 1)-1))) >= 115%, 115%, INDEX(AW4:INDEX(AW4:BH4, MATCH(2, 1/(AW4:BH4<>""), 1)-1), ROW(INDIRECT("1:" & MATCH(2, 1/(AW4:BH4<>""), 1)-1)))), 0))/_xlfn.XLOOKUP(F4,Apuração!A:A,Apuração!B:B))} -> 0.25 | BM4: {=IFERROR( INDEX($AW$1:$BH$1, _xlfn.AGGREGATE(14, 6, COLUMN($AW$1:$BH$1)/(AW4:BH4<>""), 2) - COLUMN($AW$1) + 1 ), "")} -> 46082 | BN4: {=IFERROR(INDEX($AW$1:$BH$1,1,MATCH(2,1/(AW4:BH4<>""))),"")} -> 46113 | BO4: =IFERROR(_xlfn.XLOOKUP(F4,Apuração!A:A,Apuração!C:C)/_xlfn.XLOOKUP(F4,Apuração!A:A,Apuração!B:B),0) -> 0.41666667 | BP4: =IFERROR(_xlfn.XLOOKUP(F4,Apuração!A:A,Apuração!D:D)/_xlfn.XLOOKUP(F4,Apuração!A:A,Apuração!B:B),0) -> 0.33333333 | BQ4: =IF(BK4>=BO4,0,_xlfn.XLOOKUP(F4,Apuração!A:A,Apuração!B:B)*(BO4 + (1/_xlfn.XLOOKUP(F4,Apuração!A:A,Apuração!B:B)) - BK4)) -> 1.85 | BR4: =IF(BQ4=0,0,BQ4*Z4) -> 1.85 | BS4: =IFERROR((_xlfn.XLOOKUP(F4,Apuração!A:A,Apuração!C:C)+1)/_xlfn.XLOOKUP(F4,Apuração!A:A,Apuração!B:B),0) -> 0.5
A5: POPULAÇÃO | B5: Aumenta efetividade de ações técnicas | C5: AL | D5: TODAS | E5: {=_xlfn.IFS( F5 = "A partir de Abril", "Aguardando Execução na Distribuidora", A5 = "CAPACITAÇÃO", "Em execução no Corporativo", TRUE, "Em Execução na Distribuidora" )} -> Em Execução na Distribuidora | F5: {=_xlfn.IFS( AG5 <> "", "Jan-Dez/26", AH5 <> "", "Fev-Dez/26", AI5 <> "", "Mar-Dez/26", AJ5 <> "", "Abr-Dez/26", TRUE, "A partir de Junho" )} -> Jan-Dez/26 | G5: Iniciada | H5: P1 | I5: Quantidade de soluções implementadas | J5: {=_xlfn.LET( _xlpm.actual_value_month, INDEX(T5:AE5, MATCH(DATE(YEAR(TODAY()), MONTH(TODAY()), 1), $T$1:$AE$1, 0)), IF(_xlpm.actual_value_month <> "",_xlpm.actual_value_month & " ações mensais", "") )} | K5: {=_xlfn.LET( _xlpm.sum_month, SUM(T5:AE5), IF(_xlpm.sum_month = 0, "", _xlpm.sum_month & " soluções implementadas no ano") )} | L5: Quantidade de Soluções compartilhadas e implementadas | N5: Item de controle | O5: Número absoluto | P5: - | Q5: - | R5: - | S5: - | AG5: 5 | AH5: 4 | AI5: 5 | AJ5: 3 | AS5: =IF(MONTH(TODAY())=3,SUM(T5:U5),IF(MONTH(TODAY())=4,SUM(T5:V5),IF(MONTH(TODAY())=5,SUM(T5:W5),IF(MONTH(TODAY())=6,SUM(T5:X5),IF(MONTH(TODAY())=7,SUM(T5:Y5),IF(MONTH(TODAY())=8,SUM(T5:Z5),IF(MONTH(TODAY())=9,SUM(T5:AA5),IF(MONTH(TODAY())=10,SUM(T5:AB5),IF(MONTH(TODAY())=11,SUM(T5:AC5),IF(MONTH(TODAY())=12,SUM(T5:AD5),IF(MONTH(TODAY())=1,SUM(T5:AE5),T5))))))))))) -> 0 | AT5: =SUM(AG5:AR5) -> 17 | AU5: =SUM(AG5:AR5) -> 17 | AW5: =AG5 -> 5 | AX5: =AH5 -> 4 | AY5: =AI5 -> 5 | AZ5: =AJ5 -> 3 | BI5: {=IFERROR(INDEX(AW5:BH5,1,MATCH(2,1/(AW5:BH5<>""))),"")} -> 3 | BJ5: {=IF(BM5 = "", "",IFERROR(INDEX(AW5:BH5,1,MATCH(2,1/(AW5:BH5<>""),1)-1),""))} -> 5 | BK5: =SUM(AW5:BH5) -> 17 | BL5: {=IFERROR(SUM(AW5:INDEX(AW5:BH5, MATCH(2, 1/(AW5:BH5<>""), 1) - 1))/_xlfn.XLOOKUP(F5,Apuração!A:A,Apuração!B:B),0)} -> 1.1666667 | BM5: {=IFERROR( INDEX($AW$1:$BH$1, _xlfn.AGGREGATE(14, 6, COLUMN($AW$1:$BH$1)/(AW5:BH5<>""), 2) - COLUMN($AW$1) + 1 ), "")} -> 46082 | BN5: {=IFERROR(INDEX($AW$1:$BH$1,1,MATCH(2,1/(AW5:BH5<>""))),"")} -> 46113 | BO5: =IFERROR(_xlfn.XLOOKUP(F5,Apuração!A:A,Apuração!C:C)/_xlfn.XLOOKUP(F5,Apuração!A:A,Apuração!B:B),0) -> 0.41666667 | BP5: =IFERROR(_xlfn.XLOOKUP(F5,Apuração!A:A,Apuração!D:D)/_xlfn.XLOOKUP(F5,Apuração!A:A,Apuração!B:B),0) -> 0.33333333 | BQ5: =IF(BK5>=BO5,0,_xlfn.XLOOKUP(F5,Apuração!A:A,Apuração!B:B)*(BO5 + (1/_xlfn.XLOOKUP(F5,Apuração!A:A,Apuração!B:B)) - BK5)) -> 0 | BR5: =IF(BQ5=0,0,BQ5*Z5) -> 0 | BS5: =IFERROR((_xlfn.XLOOKUP(F5,Apuração!A:A,Apuração!C:C)+1)/_xlfn.XLOOKUP(F5,Apuração!A:A,Apuração!B:B),0) -> 0.5
A6: POPULAÇÃO | B6: Aumenta efetividade de ações técnicas | C6: AL | D6: LESTE | E6: {=_xlfn.IFS( F6 = "A partir de Abril", "Aguardando Execução na Distribuidora", A6 = "CAPACITAÇÃO", "Em execução no Corporativo", TRUE, "Em Execução na Distribuidora" )} -> Em Execução na Distribuidora | F6: {=_xlfn.IFS( AG6 <> "", "Jan-Dez/26", AH6 <> "", "Fev-Dez/26", AI6 <> "", "Mar-Dez/26", AJ6 <> "", "Abr-Dez/26", TRUE, "A partir de Junho" )} -> Jan-Dez/26 | G6: Iniciada | H6: P1 | I6: Quantidade de soluções implementadas | J6: {=_xlfn.LET( _xlpm.actual_value_month, INDEX(T6:AE6, MATCH(DATE(YEAR(TODAY()), MONTH(TODAY()), 1), $T$1:$AE$1, 0)), IF(_xlpm.actual_value_month <> "",_xlpm.actual_value_month & " ações mensais", "") )} | K6: {=_xlfn.LET( _xlpm.sum_month, SUM(T6:AE6), IF(_xlpm.sum_month = 0, "", _xlpm.sum_month & " soluções implementadas no ano") )} | L6: Quantidade de Soluções compartilhadas e implementadas | N6: Item de controle | O6: Número absoluto | P6: - | Q6: - | R6: - | S6: - | AG6: 0 | AH6: 0 | AI6: 0 | AJ6: 0 | AS6: =IF(MONTH(TODAY())=3,SUM(T6:U6),IF(MONTH(TODAY())=4,SUM(T6:V6),IF(MONTH(TODAY())=5,SUM(T6:W6),IF(MONTH(TODAY())=6,SUM(T6:X6),IF(MONTH(TODAY())=7,SUM(T6:Y6),IF(MONTH(TODAY())=8,SUM(T6:Z6),IF(MONTH(TODAY())=9,SUM(T6:AA6),IF(MONTH(TODAY())=10,SUM(T6:AB6),IF(MONTH(TODAY())=11,SUM(T6:AC6),IF(MONTH(TODAY())=12,SUM(T6:AD6),IF(MONTH(TODAY())=1,SUM(T6:AE6),T6))))))))))) -> 0 | AT6: =SUM(AG6:AR6) -> 0 | AU6: =SUM(AG6:AR6) -> 0 | AW6: =AG6 -> 0 | AX6: =AH6 -> 0 | AY6: =AI6 -> 0 | AZ6: =AJ6 -> 0 | BI6: {=IFERROR(INDEX(AW6:BH6,1,MATCH(2,1/(AW6:BH6<>""))),"")} -> 0 | BJ6: {=IF(BM6 = "", "",IFERROR(INDEX(AW6:BH6,1,MATCH(2,1/(AW6:BH6<>""),1)-1),""))} -> 0 | BK6: =SUM(AW6:BH6) -> 0 | BL6: {=IFERROR(SUM(AW6:INDEX(AW6:BH6, MATCH(2, 1/(AW6:BH6<>""), 1) - 1))/_xlfn.XLOOKUP(F6,Apuração!A:A,Apuração!B:B),0)} -> 0 | BM6: {=IFERROR( INDEX($AW$1:$BH$1, _xlfn.AGGREGATE(14, 6, COLUMN($AW$1:$BH$1)/(AW6:BH6<>""), 2) - COLUMN($AW$1) + 1 ), "")} -> 46082 | BN6: {=IFERROR(INDEX($AW$1:$BH$1,1,MATCH(2,1/(AW6:BH6<>""))),"")} -> 46113 | BO6: =IFERROR(_xlfn.XLOOKUP(F6,Apuração!A:A,Apuração!C:C)/_xlfn.XLOOKUP(F6,Apuração!A:A,Apuração!B:B),0) -> 0.41666667 | BP6: =IFERROR(_xlfn.XLOOKUP(F6,Apuração!A:A,Apuração!D:D)/_xlfn.XLOOKUP(F6,Apuração!A:A,Apuração!B:B),0) -> 0.33333333 | BQ6: =IF(BK6>=BO6,0,_xlfn.XLOOKUP(F6,Apuração!A:A,Apuração!B:B)*(BO6 + (1/_xlfn.XLOOKUP(F6,Apuração!A:A,Apuração!B:B)) - BK6)) -> 6 | BR6: =IF(BQ6=0,0,BQ6*Z6) -> 0 | BS6: =IFERROR((_xlfn.XLOOKUP(F6,Apuração!A:A,Apuração!C:C)+1)/_xlfn.XLOOKUP(F6,Apuração!A:A,Apuração!B:B),0) -> 0.5
A7: POPULAÇÃO | B7: Aumenta efetividade de ações técnicas | C7: AL | D7: OESTE | E7: {=_xlfn.IFS( F7 = "A partir de Abril", "Aguardando Execução na Distribuidora", A7 = "CAPACITAÇÃO", "Em execução no Corporativo", TRUE, "Em Execução na Distribuidora" )} -> Em Execução na Distribuidora | F7: {=_xlfn.IFS( AG7 <> "", "Jan-Dez/26", AH7 <> "", "Fev-Dez/26", AI7 <> "", "Mar-Dez/26", AJ7 <> "", "Abr-Dez/26", TRUE, "A partir de Junho" )} -> Jan-Dez/26 | G7: Iniciada | H7: P1 | I7: Quantidade de soluções implementadas | J7: {=_xlfn.LET( _xlpm.actual_value_month, INDEX(T7:AE7, MATCH(DATE(YEAR(TODAY()), MONTH(TODAY()), 1), $T$1:$AE$1, 0)), IF(_xlpm.actual_value_month <> "",_xlpm.actual_value_month & " ações mensais", "") )} | K7: {=_xlfn.LET( _xlpm.sum_month, SUM(T7:AE7), IF(_xlpm.sum_month = 0, "", _xlpm.sum_month & " soluções implementadas no ano") )} | L7: Quantidade de Soluções compartilhadas e implementadas | N7: Item de controle | O7: Número absoluto | P7: - | Q7: - | R7: - | S7: - | AG7: 5 | AH7: 4 | AI7: 5 | AJ7: 3 | AS7: =IF(MONTH(TODAY())=3,SUM(T7:U7),IF(MONTH(TODAY())=4,SUM(T7:V7),IF(MONTH(TODAY())=5,SUM(T7:W7),IF(MONTH(TODAY())=6,SUM(T7:X7),IF(MONTH(TODAY())=7,SUM(T7:Y7),IF(MONTH(TODAY())=8,SUM(T7:Z7),IF(MONTH(TODAY())=9,SUM(T7:AA7),IF(MONTH(TODAY())=10,SUM(T7:AB7),IF(MONTH(TODAY())=11,SUM(T7:AC7),IF(MONTH(TODAY())=12,SUM(T7:AD7),IF(MONTH(TODAY())=1,SUM(T7:AE7),T7))))))))))) -> 0 | AT7: =SUM(AG7:AR7) -> 17 | AU7: =SUM(AG7:AR7) -> 17 | AW7: =AG7 -> 5 | AX7: =AH7 -> 4 | AY7: =AI7 -> 5 | AZ7: =AJ7 -> 3 | BI7: {=IFERROR(INDEX(AW7:BH7,1,MATCH(2,1/(AW7:BH7<>""))),"")} -> 3 | BJ7: {=IF(BM7 = "", "",IFERROR(INDEX(AW7:BH7,1,MATCH(2,1/(AW7:BH7<>""),1)-1),""))} -> 5 | BK7: =SUM(AW7:BH7) -> 17 | BL7: {=IFERROR(SUM(AW7:INDEX(AW7:BH7, MATCH(2, 1/(AW7:BH7<>""), 1) - 1))/_xlfn.XLOOKUP(F7,Apuração!A:A,Apuração!B:B),0)} -> 1.1666667 | BM7: {=IFERROR( INDEX($AW$1:$BH$1, _xlfn.AGGREGATE(14, 6, COLUMN($AW$1:$BH$1)/(AW7:BH7<>""), 2) - COLUMN($AW$1) + 1 ), "")} -> 46082 | BN7: {=IFERROR(INDEX($AW$1:$BH$1,1,MATCH(2,1/(AW7:BH7<>""))),"")} -> 46113 | BO7: =IFERROR(_xlfn.XLOOKUP(F7,Apuração!A:A,Apuração!C:C)/_xlfn.XLOOKUP(F7,Apuração!A:A,Apuração!B:B),0) -> 0.41666667 | BP7: =IFERROR(_xlfn.XLOOKUP(F7,Apuração!A:A,Apuração!D:D)/_xlfn.XLOOKUP(F7,Apuração!A:A,Apuração!B:B),0) -> 0.33333333 | BQ7: =IF(BK7>=BO7,0,_xlfn.XLOOKUP(F7,Apuração!A:A,Apuração!B:B)*(BO7 + (1/_xlfn.XLOOKUP(F7,Apuração!A:A,Apuração!B:B)) - BK7)) -> 0 | BR7: =IF(BQ7=0,0,BQ7*Z7) -> 0 | BS7: =IFERROR((_xlfn.XLOOKUP(F7,Apuração!A:A,Apuração!C:C)+1)/_xlfn.XLOOKUP(F7,Apuração!A:A,Apuração!B:B),0) -> 0.5
A8: POPULAÇÃO | B8: E+ Segurança : parceiros estratégicos | C8: AL | D8: TODAS | E8: {=_xlfn.IFS( F8 = "A partir de Abril", "Aguardando Execução na Distribuidora", A8 = "CAPACITAÇÃO", "Em execução no Corporativo", TRUE, "Em Execução na Distribuidora" )} -> Em Execução na Distribuidora | F8: {=_xlfn.IFS( AG8 <> "", "Jan-Dez/26", AH8 <> "", "Fev-Dez/26", AI8 <> "", "Mar-Dez/26", AJ8 <> "", "Abr-Dez/26", TRUE, "A partir de Junho" )} -> Jan-Dez/26 | G8: Iniciada | H8: P3 | I8: (N° de ações planejadas/N° de ações realizadas)*100 | J8: {=_xlfn.LET( _xlpm.actual_value_month, INDEX(T8:AE8, MATCH(DATE(YEAR(TODAY()), MONTH(TODAY()), 1), $T$1:$AE$1, 0)), IF(_xlpm.actual_value_month <> "",_xlpm.actual_value_month & " eventos mensais", "") )} -> 1 eventos mensais | K8: {=_xlfn.LET( _xlpm.sum_month, SUM(T8:AE8), IF(_xlpm.sum_month = 0, "", _xlpm.sum_month & " eventos no ano") )} -> 24 eventos no ano | L8: Quantidade de eventos realizados​ | M8: 01 evento com empresas parceiras | N8: Indicador | O8: Percentual | P8: Seg Comunidade | Q8: - | R8: Índice de Compromisso com a Cultura de Segurança (ICCS) | S8: Indicadores de impacto e compromisso em segurança | T8: 7 | U8: 1 | V8: 7 | W8: 1 | X8: 1 | Y8: 1 | Z8: 1 | AA8: 1 | AB8: 1 | AC8: 1 | AD8: 1 | AE8: 1 | AG8: 7 | AH8: 1 | AI8: 7 | AJ8: 3 | AS8: =IF(MONTH(TODAY())=3,SUM(T8:U8),IF(MONTH(TODAY())=4,SUM(T8:V8),IF(MONTH(TODAY())=5,SUM(T8:W8),IF(MONTH(TODAY())=6,SUM(T8:X8),IF(MONTH(TODAY())=7,SUM(T8:Y8),IF(MONTH(TODAY())=8,SUM(T8:Z8),IF(MONTH(TODAY())=9,SUM(T8:AA8),IF(MONTH(TODAY())=10,SUM(T8:AB8),IF(MONTH(TODAY())=11,SUM(T8:AC8),IF(MONTH(TODAY())=12,SUM(T8:AD8),IF(MONTH(TODAY())=1,SUM(T8:AE8),T8))))))))))) -> 17 | AT8: =SUM(IF(AW8<1.15,AG8,1.15*T8),IF(AX8<1.15,AH8,1.15*U8),IF(AY8<1.15,AI8,1.15*V8),IF(AZ8<1.15,AJ8,1.15*W8),IF(BA8<1.15,AK8,1.15*X8),IF(BB8<1.15,AL8,1.15*Y8),IF(BC8<1.15,AM8,1.15*Z8),IF(BD8<1.15,AN8,1.15*AA8),IF(BE8<1.15,AO8,1.15*AB8),IF(BF8<1.15,AP8,1.15*AC8),IF(BG8<1.15,AQ8,1.15*AD8),IF(BH8<1.15,AR8,1.15*AE8)) -> 16.15 | AU8: =SUM(AG8:AR8) -> 18 | AW8: =IFERROR(IF(AG8="",0,AG8/T8),0) -> 1 | AX8: =IFERROR(IF(AH8="",0,AH8/U8),0) -> 1 | AY8: =IFERROR(IF(AI8="",0,AI8/V8),0) -> 1 | AZ8: =IFERROR(IF(AJ8="",0,AJ8/W8),0) -> 3 | BI8: {=IFERROR(INDEX(AW8:BH8,1,MATCH(2,1/(AW8:BH8<>""))),"")} -> 3 | BJ8: {=IF(BM8 = "", "",IFERROR(INDEX(AW8:BH8,1,MATCH(2,1/(AW8:BH8<>""),1)-1),""))} -> 1 | BK8: =IF((IF(AW8>=115%,115%,AW8) + IF(AX8>=115%,115%,AX8) + IF(AY8>=115%,115%,AY8) + (IF(AZ8>=115%,115%,AZ8) + IF(BA8>=115%,115%,BA8) + IF(BB8>=115%,115%,BB8) + IF(BC8>=115%,115%,BC8) + IF(BD8>=115%,115%,BD8) + IF(BE8>=115%,115%,BE8) + IF(BF8>=136%,136%,BF8) + IF(BG8>=115%,115%,BG8) + IF(BH8>=115%,115%,BH8)))/_xlfn.XLOOKUP(F8,Apuração!A:A,Apuração!B:B)>=1.15,1.15,((IF(AZ8>=115%,115%,AZ8) + IF(AX8>=115%,115%,AX8) + IF(AY8>=115%,115%,AY8) + (IF(AW8>=115%,115%,AW8) + IF(BA8>=115%,115%,BA8) + IF(BB8>=115%,115%,BB8) + IF(BC8>=115%,115%,BC8) + IF(BD8>=115%,115%,BD8) + IF(BE8>=115%,115%,BE8) + IF(BF8>=136%,136%,BF8) + IF(BG8>=115%,115%,BG8) + IF(BH8>=115%,115%,BH8)))/_xlfn.XLOOKUP(F8,Apuração!A:A,Apuração!B:B))) -> 0.34583333 | BL8: {=IF(SUM(IFERROR(IF(INDEX(AW8:INDEX(AW8:BH8, MATCH(2, 1/(AW8:BH8<>""), 1)-1), ROW(INDIRECT("1:" & MATCH(2, 1/(AW8:BH8<>""), 1)-1))) >= 115%, 115%, INDEX(AW8:INDEX(AW8:BH8, MATCH(2, 1/(AW8:BH8<>""), 1)-1), ROW(INDIRECT("1:" & MATCH(2, 1/(AW8:BH8<>""), 1)-1)))), 0))/_xlfn.XLOOKUP(F8,Apuração!A:A,Apuração!B:B)>=1.15,1.15,SUM(IFERROR(IF(INDEX(AW8:INDEX(AW8:BH8, MATCH(2, 1/(AW8:BH8<>""), 1)-1), ROW(INDIRECT("1:" & MATCH(2, 1/(AW8:BH8<>""), 1)-1))) >= 115%, 115%, INDEX(AW8:INDEX(AW8:BH8, MATCH(2, 1/(AW8:BH8<>""), 1)-1), ROW(INDIRECT("1:" & MATCH(2, 1/(AW8:BH8<>""), 1)-1)))), 0))/_xlfn.XLOOKUP(F8,Apuração!A:A,Apuração!B:B))} -> 0.25 | BM8: {=IFERROR( INDEX($AW$1:$BH$1, _xlfn.AGGREGATE(14, 6, COLUMN($AW$1:$BH$1)/(AW8:BH8<>""), 2) - COLUMN($AW$1) + 1 ), "")} -> 46082 | BN8: {=IFERROR(INDEX($AW$1:$BH$1,1,MATCH(2,1/(AW8:BH8<>""))),"")} -> 46113 | BO8: =IFERROR(_xlfn.XLOOKUP(F8,Apuração!A:A,Apuração!C:C)/_xlfn.XLOOKUP(F8,Apuração!A:A,Apuração!B:B),0) -> 0.41666667 | BP8: =IFERROR(_xlfn.XLOOKUP(F8,Apuração!A:A,Apuração!D:D)/_xlfn.XLOOKUP(F8,Apuração!A:A,Apuração!B:B),0) -> 0.33333333 | BQ8: =IF(BK8>=BO8,0,_xlfn.XLOOKUP(F8,Apuração!A:A,Apuração!B:B)*(BO8 + (1/_xlfn.XLOOKUP(F8,Apuração!A:A,Apuração!B:B)) - BK8)) -> 1.85 | BR8: =IF(BQ8=0,0,BQ8*Z8) -> 1.85 | BS8: =IFERROR((_xlfn.XLOOKUP(F8,Apuração!A:A,Apuração!C:C)+1)/_xlfn.XLOOKUP(F8,Apuração!A:A,Apuração!B:B),0) -> 0.5
A9: POPULAÇÃO | B9: E+ Segurança : parceiros estratégicos | C9: AL | D9: LESTE | E9: {=_xlfn.IFS( F9 = "A partir de Abril", "Aguardando Execução na Distribuidora", A9 = "CAPACITAÇÃO", "Em execução no Corporativo", TRUE, "Em Execução na Distribuidora" )} -> Em Execução na Distribuidora | F9: {=_xlfn.IFS( AG9 <> "", "Jan-Dez/26", AH9 <> "", "Fev-Dez/26", AI9 <> "", "Mar-Dez/26", AJ9 <> "", "Abr-Dez/26", TRUE, "A partir de Junho" )} -> A partir de Junho | G9: Iniciada | H9: P3 | I9: (N° de ações planejadas/N° de ações realizadas)*100 | J9: {=_xlfn.LET( _xlpm.actual_value_month, INDEX(T9:AE9, MATCH(DATE(YEAR(TODAY()), MONTH(TODAY()), 1), $T$1:$AE$1, 0)), IF(_xlpm.actual_value_month <> "",_xlpm.actual_value_month & " eventos mensais", "") )} -> 1 eventos mensais | K9: {=_xlfn.LET( _xlpm.sum_month, SUM(T9:AE9), IF(_xlpm.sum_month = 0, "", _xlpm.sum_month & " eventos no ano") )} -> 9 eventos no ano | L9: Quantidade de eventos realizados​ | M9: 01 evento com empresas parceiras | N9: Indicador | O9: Percentual | P9: Seg Comunidade | Q9: - | R9: Índice de Compromisso com a Cultura de Segurança (ICCS) | S9: Indicadores de impacto e compromisso em segurança | W9: 1 | X9: 1 | Y9: 1 | Z9: 1 | AA9: 1 | AB9: 1 | AC9: 1 | AD9: 1 | AE9: 1 | AS9: =IF(MONTH(TODAY())=3,SUM(T9:U9),IF(MONTH(TODAY())=4,SUM(T9:V9),IF(MONTH(TODAY())=5,SUM(T9:W9),IF(MONTH(TODAY())=6,SUM(T9:X9),IF(MONTH(TODAY())=7,SUM(T9:Y9),IF(MONTH(TODAY())=8,SUM(T9:Z9),IF(MONTH(TODAY())=9,SUM(T9:AA9),IF(MONTH(TODAY())=10,SUM(T9:AB9),IF(MONTH(TODAY())=11,SUM(T9:AC9),IF(MONTH(TODAY())=12,SUM(T9:AD9),IF(MONTH(TODAY())=1,SUM(T9:AE9),T9))))))))))) -> 2 | AT9: =SUM(IF(AW9<1.15,AG9,1.15*T9),IF(AX9<1.15,AH9,1.15*U9),IF(AY9<1.15,AI9,1.15*V9),IF(AZ9<1.15,AJ9,1.15*W9),IF(BA9<1.15,AK9,1.15*X9),IF(BB9<1.15,AL9,1.15*Y9),IF(BC9<1.15,AM9,1.15*Z9),IF(BD9<1.15,AN9,1.15*AA9),IF(BE9<1.15,AO9,1.15*AB9),IF(BF9<1.15,AP9,1.15*AC9),IF(BG9<1.15,AQ9,1.15*AD9),IF(BH9<1.15,AR9,1.15*AE9)) -> 0 | AU9: =SUM(AG9:AR9) -> 0 | AW9: =IFERROR(IF(AG9="",0,AG9/T9),0) -> 0 | AX9: =IFERROR(IF(AH9="",0,AH9/U9),0) -> 0 | AY9: =IFERROR(IF(AI9="",0,AI9/V9),0) -> 0 | AZ9: =IFERROR(IF(AJ9="",0,AJ9/W9),0) -> 0 | BI9: {=IFERROR(INDEX(AW9:BH9,1,MATCH(2,1/(AW9:BH9<>""))),"")} -> 0 | BJ9: {=IF(BM9 = "", "",IFERROR(INDEX(AW9:BH9,1,MATCH(2,1/(AW9:BH9<>""),1)-1),""))} -> 0 | BK9: =IF((IF(AW9>=115%,115%,AW9) + IF(AX9>=115%,115%,AX9) + IF(AY9>=115%,115%,AY9) + (IF(AZ9>=115%,115%,AZ9) + IF(BA9>=115%,115%,BA9) + IF(BB9>=115%,115%,BB9) + IF(BC9>=115%,115%,BC9) + IF(BD9>=115%,115%,BD9) + IF(BE9>=115%,115%,BE9) + IF(BF9>=136%,136%,BF9) + IF(BG9>=115%,115%,BG9) + IF(BH9>=115%,115%,BH9)))/_xlfn.XLOOKUP(F9,Apuração!A:A,Apuração!B:B)>=1.15,1.15,((IF(AZ9>=115%,115%,AZ9) + IF(AX9>=115%,115%,AX9) + IF(AY9>=115%,115%,AY9) + (IF(AW9>=115%,115%,AW9) + IF(BA9>=115%,115%,BA9) + IF(BB9>=115%,115%,BB9) + IF(BC9>=115%,115%,BC9) + IF(BD9>=115%,115%,BD9) + IF(BE9>=115%,115%,BE9) + IF(BF9>=136%,136%,BF9) + IF(BG9>=115%,115%,BG9) + IF(BH9>=115%,115%,BH9)))/_xlfn.XLOOKUP(F9,Apuração!A:A,Apuração!B:B))) -> 0 | BL9: {=IF(SUM(IFERROR(IF(INDEX(AW9:INDEX(AW9:BH9, MATCH(2, 1/(AW9:BH9<>""), 1)-1), ROW(INDIRECT("1:" & MATCH(2, 1/(AW9:BH9<>""), 1)-1))) >= 115%, 115%, INDEX(AW9:INDEX(AW9:BH9, MATCH(2, 1/(AW9:BH9<>""), 1)-1), ROW(INDIRECT("1:" & MATCH(2, 1/(AW9:BH9<>""), 1)-1)))), 0))/_xlfn.XLOOKUP(F9,Apuração!A:A,Apuração!B:B)>=1.15,1.15,SUM(IFERROR(IF(INDEX(AW9:INDEX(AW9:BH9, MATCH(2, 1/(AW9:BH9<>""), 1)-1), ROW(INDIRECT("1:" & MATCH(2, 1/(AW9:BH9<>""), 1)-1))) >= 115%, 115%, INDEX(AW9:INDEX(AW9:BH9, MATCH(2, 1/(AW9:BH9<>""), 1)-1), ROW(INDIRECT("1:" & MATCH(2, 1/(AW9:BH9<>""), 1)-1)))), 0))/_xlfn.XLOOKUP(F9,Apuração!A:A,Apuração!B:B))} -> 0 | BM9: {=IFERROR( INDEX($AW$1:$BH$1, _xlfn.AGGREGATE(14, 6, COLUMN($AW$1:$BH$1)/(AW9:BH9<>""), 2) - COLUMN($AW$1) + 1 ), "")} -> 46082 | BN9: {=IFERROR(INDEX($AW$1:$BH$1,1,MATCH(2,1/(AW9:BH9<>""))),"")} -> 46113 | BO9: =IFERROR(_xlfn.XLOOKUP(F9,Apuração!A:A,Apuração!C:C)/_xlfn.XLOOKUP(F9,Apuração!A:A,Apuração!B:B),0) -> 0 | BP9: =IFERROR(_xlfn.XLOOKUP(F9,Apuração!A:A,Apuração!D:D)/_xlfn.XLOOKUP(F9,Apuração!A:A,Apuração!B:B),0) -> 0 | BQ9: =IF(BK9>=BO9,0,_xlfn.XLOOKUP(F9,Apuração!A:A,Apuração!B:B)*(BO9 + (1/_xlfn.XLOOKUP(F9,Apuração!A:A,Apuração!B:B)) - BK9)) -> 0 | BR9: =IF(BQ9=0,0,BQ9*Z9) -> 0 | BS9: =IFERROR((_xlfn.XLOOKUP(F9,Apuração!A:A,Apuração!C:C)+1)/_xlfn.XLOOKUP(F9,Apuração!A:A,Apuração!B:B),0) -> 0.14285714
A10: POPULAÇÃO | B10: E+ Segurança : parceiros estratégicos | C10: AL | D10: OESTE | E10: {=_xlfn.IFS( F10 = "A partir de Abril", "Aguardando Execução na Distribuidora", A10 = "CAPACITAÇÃO", "Em execução no Corporativo", TRUE, "Em Execução na Distribuidora" )} -> Em Execução na Distribuidora | F10: {=_xlfn.IFS( AG10 <> "", "Jan-Dez/26", AH10 <> "", "Fev-Dez/26", AI10 <> "", "Mar-Dez/26", AJ10 <> "", "Abr-Dez/26", TRUE, "A partir de Junho" )} -> Jan-Dez/26 | G10: Iniciada | H10: P3 | I10: (N° de ações planejadas/N° de ações realizadas)*100 | J10: {=_xlfn.LET( _xlpm.actual_value_month, INDEX(T10:AE10, MATCH(DATE(YEAR(TODAY()), MONTH(TODAY()), 1), $T$1:$AE$1, 0)), IF(_xlpm.actual_value_month <> "",_xlpm.actual_value_month & " eventos mensais", "") )} -> 1 eventos mensais | K10: {=_xlfn.LET( _xlpm.sum_month, SUM(T10:AE10), IF(_xlpm.sum_month = 0, "", _xlpm.sum_month & " eventos no ano") )} -> 24 eventos no ano | L10: Quantidade de eventos realizados​ | M10: 01 evento com empresas parceiras | N10: Indicador | O10: Percentual | P10: Seg Comunidade | Q10: - | R10: Índice de Compromisso com a Cultura de Segurança (ICCS) | S10: Indicadores de impacto e compromisso em segurança | T10: 7 | U10: 1 | V10: 7 | W10: 1 | X10: 1 | Y10: 1 | Z10: 1 | AA10: 1 | AB10: 1 | AC10: 1 | AD10: 1 | AE10: 1 | AG10: 7 | AH10: 1 | AI10: 7 | AJ10: 3 | AS10: =IF(MONTH(TODAY())=3,SUM(T10:U10),IF(MONTH(TODAY())=4,SUM(T10:V10),IF(MONTH(TODAY())=5,SUM(T10:W10),IF(MONTH(TODAY())=6,SUM(T10:X10),IF(MONTH(TODAY())=7,SUM(T10:Y10),IF(MONTH(TODAY())=8,SUM(T10:Z10),IF(MONTH(TODAY())=9,SUM(T10:AA10),IF(MONTH(TODAY())=10,SUM(T10:AB10),IF(MONTH(TODAY())=11,SUM(T10:AC10),IF(MONTH(TODAY())=12,SUM(T10:AD10),IF(MONTH(TODAY())=1,SUM(T10:AE10),T10))))))))))) -> 17 | AT10: =SUM(IF(AW10<1.15,AG10,1.15*T10),IF(AX10<1.15,AH10,1.15*U10),IF(AY10<1.15,AI10,1.15*V10),IF(AZ10<1.15,AJ10,1.15*W10),IF(BA10<1.15,AK10,1.15*X10),IF(BB10<1.15,AL10,1.15*Y10),IF(BC10<1.15,AM10,1.15*Z10),IF(BD10<1.15,AN10,1.15*AA10),IF(BE10<1.15,AO10,1.15*AB10),IF(BF10<1.15,AP10,1.15*AC10),IF(BG10<1.15,AQ10,1.15*AD10),IF(BH10<1.15,AR10,1.15*AE10)) -> 16.15 | AU10: =SUM(AG10:AR10) -> 18 | AW10: =IFERROR(IF(AG10="",0,AG10/T10),0) -> 1 | AX10: =IFERROR(IF(AH10="",0,AH10/U10),0) -> 1 | AY10: =IFERROR(IF(AI10="",0,AI10/V10),0) -> 1 | AZ10: =IFERROR(IF(AJ10="",0,AJ10/W10),0) -> 3 | BI10: {=IFERROR(INDEX(AW10:BH10,1,MATCH(2,1/(AW10:BH10<>""))),"")} -> 3 | BJ10: {=IF(BM10 = "", "",IFERROR(INDEX(AW10:BH10,1,MATCH(2,1/(AW10:BH10<>""),1)-1),""))} -> 1 | BK10: =IF((IF(AW10>=115%,115%,AW10) + IF(AX10>=115%,115%,AX10) + IF(AY10>=115%,115%,AY10) + (IF(AZ10>=115%,115%,AZ10) + IF(BA10>=115%,115%,BA10) + IF(BB10>=115%,115%,BB10) + IF(BC10>=115%,115%,BC10) + IF(BD10>=115%,115%,BD10) + IF(BE10>=115%,115%,BE10) + IF(BF10>=136%,136%,BF10) + IF(BG10>=115%,115%,BG10) + IF(BH10>=115%,115%,BH10)))/_xlfn.XLOOKUP(F10,Apuração!A:A,Apuração!B:B)>=1.15,1.15,((IF(AZ10>=115%,115%,AZ10) + IF(AX10>=115%,115%,AX10) + IF(AY10>=115%,115%,AY10) + (IF(AW10>=115%,115%,AW10) + IF(BA10>=115%,115%,BA10) + IF(BB10>=115%,115%,BB10) + IF(BC10>=115%,115%,BC10) + IF(BD10>=115%,115%,BD10) + IF(BE10>=115%,115%,BE10) + IF(BF10>=136%,136%,BF10) + IF(BG10>=115%,115%,BG10) + IF(BH10>=115%,115%,BH10)))/_xlfn.XLOOKUP(F10,Apuração!A:A,Apuração!B:B))) -> 0.34583333 | BL10: {=IF(SUM(IFERROR(IF(INDEX(AW10:INDEX(AW10:BH10, MATCH(2, 1/(AW10:BH10<>""), 1)-1), ROW(INDIRECT("1:" & MATCH(2, 1/(AW10:BH10<>""), 1)-1))) >= 115%, 115%, INDEX(AW10:INDEX(AW10:BH10, MATCH(2, 1/(AW10:BH10<>""), 1)-1), ROW(INDIRECT("1:" & MATCH(2, 1/(AW10:BH10<>""), 1)-1)))), 0))/_xlfn.XLOOKUP(F10,Apuração!A:A,Apuração!B:B)>=1.15,1.15,SUM(IFERROR(IF(INDEX(AW10:INDEX(AW10:BH10, MATCH(2, 1/(AW10:BH10<>""), 1)-1), ROW(INDIRECT("1:" & MATCH(2, 1/(AW10:BH10<>""), 1)-1))) >= 115%, 115%, INDEX(AW10:INDEX(AW10:BH10, MATCH(2, 1/(AW10:BH10<>""), 1)-1), ROW(INDIRECT("1:" & MATCH(2, 1/(AW10:BH10<>""), 1)-1)))), 0))/_xlfn.XLOOKUP(F10,Apuração!A:A,Apuração!B:B))} -> 0.25 | BM10: {=IFERROR( INDEX($AW$1:$BH$1, _xlfn.AGGREGATE(14, 6, COLUMN($AW$1:$BH$1)/(AW10:BH10<>""), 2) - COLUMN($AW$1) + 1 ), "")} -> 46082 | BN10: {=IFERROR(INDEX($AW$1:$BH$1,1,MATCH(2,1/(AW10:BH10<>""))),"")} -> 46113 | BO10: =IFERROR(_xlfn.XLOOKUP(F10,Apuração!A:A,Apuração!C:C)/_xlfn.XLOOKUP(F10,Apuração!A:A,Apuração!B:B),0) -> 0.41666667 | BP10: =IFERROR(_xlfn.XLOOKUP(F10,Apuração!A:A,Apuração!D:D)/_xlfn.XLOOKUP(F10,Apuração!A:A,Apuração!B:B),0) -> 0.33333333 | BQ10: =IF(BK10>=BO10,0,_xlfn.XLOOKUP(F10,Apuração!A:A,Apuração!B:B)*(BO10 + (1/_xlfn.XLOOKUP(F10,Apuração!A:A,Apuração!B:B)) - BK10)) -> 1.85 | BR10: =IF(BQ10=0,0,BQ10*Z10) -> 1.85 | BS10: =IFERROR((_xlfn.XLOOKUP(F10,Apuração!A:A,Apuração!C:C)+1)/_xlfn.XLOOKUP(F10,Apuração!A:A,Apuração!B:B),0) -> 0.5
A11: POPULAÇÃO | B11: E+ Segurança : parceiros estratégicos | C11: AL | D11: TODAS | E11: {=_xlfn.IFS( F11 = "A partir de Abril", "Aguardando Execução na Distribuidora", A11 = "CAPACITAÇÃO", "Em execução no Corporativo", TRUE, "Em Execução na Distribuidora" )} -> Em Execução na Distribuidora | F11: {=_xlfn.IFS( AG11 <> "", "Jan-Dez/26", AH11 <> "", "Fev-Dez/26", AI11 <> "", "Mar-Dez/26", AJ11 <> "", "Abr-Dez/26", TRUE, "A partir de Junho" )} -> Jan-Dez/26 | G11: Iniciada | H11: P3 | I11: Número de profissionais diretamente impactados | J11: {=_xlfn.LET( _xlpm.actual_value_month, INDEX(T11:AE11, MATCH(DATE(YEAR(TODAY()), MONTH(TODAY()), 1), $T$1:$AE$1, 0)), IF(_xlpm.actual_value_month <> "",_xlpm.actual_value_month & " ações mensais", "") )} | K11: {=_xlfn.LET( _xlpm.sum_month, SUM(T11:AE11), IF(_xlpm.sum_month = 0, "", _xlpm.sum_month & " pessoas impactadas no ano") )} | L11: Número de profissionais diretamente impactados | M11: 1 | N11: Item de controle | O11: Número absoluto | P11: - | Q11: - | R11: - | S11: - | AG11: 259 | AH11: 0 | AI11: 114 | AJ11: 57 | AS11: =IF(MONTH(TODAY())=3,SUM(T11:U11),IF(MONTH(TODAY())=4,SUM(T11:V11),IF(MONTH(TODAY())=5,SUM(T11:W11),IF(MONTH(TODAY())=6,SUM(T11:X11),IF(MONTH(TODAY())=7,SUM(T11:Y11),IF(MONTH(TODAY())=8,SUM(T11:Z11),IF(MONTH(TODAY())=9,SUM(T11:AA11),IF(MONTH(TODAY())=10,SUM(T11:AB11),IF(MONTH(TODAY())=11,SUM(T11:AC11),IF(MONTH(TODAY())=12,SUM(T11:AD11),IF(MONTH(TODAY())=1,SUM(T11:AE11),T11))))))))))) -> 0 | AT11: =SUM(AG11:AR11) -> 430 | AU11: =SUM(AG11:AR11) -> 430 | AW11: =AG11 -> 259 | AX11: =AH11 -> 0 | AY11: =AI11 -> 114 | AZ11: =AJ11 -> 57 | BI11: {=IFERROR(INDEX(AW11:BH11,1,MATCH(2,1/(AW11:BH11<>""))),"")} -> 57 | BJ11: {=IF(BM11 = "", "",IFERROR(INDEX(AW11:BH11,1,MATCH(2,1/(AW11:BH11<>""),1)-1),""))} -> 114 | BK11: =SUM(AW11:BH11) -> 430 | BL11: {=IFERROR(SUM(AW11:INDEX(AW11:BH11, MATCH(2, 1/(AW11:BH11<>""), 1) - 1))/_xlfn.XLOOKUP(F11,Apuração!A:A,Apuração!B:B),0)} -> 31.083333 | BM11: {=IFERROR( INDEX($AW$1:$BH$1, _xlfn.AGGREGATE(14, 6, COLUMN($AW$1:$BH$1)/(AW11:BH11<>""), 2) - COLUMN($AW$1) + 1 ), "")} -> 46082 | BN11: {=IFERROR(INDEX($AW$1:$BH$1,1,MATCH(2,1/(AW11:BH11<>""))),"")} -> 46113 | BO11: =IFERROR(_xlfn.XLOOKUP(F11,Apuração!A:A,Apuração!C:C)/_xlfn.XLOOKUP(F11,Apuração!A:A,Apuração!B:B),0) -> 0.41666667 | BP11: =IFERROR(_xlfn.XLOOKUP(F11,Apuração!A:A,Apuração!D:D)/_xlfn.XLOOKUP(F11,Apuração!A:A,Apuração!B:B),0) -> 0.33333333 | BQ11: =IF(BK11>=BO11,0,_xlfn.XLOOKUP(F11,Apuração!A:A,Apuração!B:B)*(BO11 + (1/_xlfn.XLOOKUP(F11,Apuração!A:A,Apuração!B:B)) - BK11)) -> 0 | BR11: =IF(BQ11=0,0,BQ11*Z11) -> 0 | BS11: =IFERROR((_xlfn.XLOOKUP(F11,Apuração!A:A,Apuração!C:C)+1)/_xlfn.XLOOKUP(F11,Apuração!A:A,Apuração!B:B),0) -> 0.5
A12: POPULAÇÃO | B12: E+ Segurança : parceiros estratégicos | C12: AL | D12: LESTE | E12: {=_xlfn.IFS( F12 = "A partir de Abril", "Aguardando Execução na Distribuidora", A12 = "CAPACITAÇÃO", "Em execução no Corporativo", TRUE, "Em Execução na Distribuidora" )} -> Em Execução na Distribuidora | F12: {=_xlfn.IFS( AG12 <> "", "Jan-Dez/26", AH12 <> "", "Fev-Dez/26", AI12 <> "", "Mar-Dez/26", AJ12 <> "", "Abr-Dez/26", TRUE, "A partir de Junho" )} -> Jan-Dez/26 | G12: Iniciada | H12: P3 | I12: Número de profissionais diretamente impactados | J12: {=_xlfn.LET( _xlpm.actual_value_month, INDEX(T12:AE12, MATCH(DATE(YEAR(TODAY()), MONTH(TODAY()), 1), $T$1:$AE$1, 0)), IF(_xlpm.actual_value_month <> "",_xlpm.actual_value_month & " ações mensais", "") )} | K12: {=_xlfn.LET( _xlpm.sum_month, SUM(T12:AE12), IF(_xlpm.sum_month = 0, "", _xlpm.sum_month & " pessoas impactadas no ano") )} | L12: Número de profissionais diretamente impactados | M12: 1 | N12: Item de controle | O12: Número absoluto | P12: - | Q12: - | R12: - | S12: - | AG12: 0 | AH12: 0 | AI12: 0 | AJ12: 0 | AS12: =IF(MONTH(TODAY())=3,SUM(T12:U12),IF(MONTH(TODAY())=4,SUM(T12:V12),IF(MONTH(TODAY())=5,SUM(T12:W12),IF(MONTH(TODAY())=6,SUM(T12:X12),IF(MONTH(TODAY())=7,SUM(T12:Y12),IF(MONTH(TODAY())=8,SUM(T12:Z12),IF(MONTH(TODAY())=9,SUM(T12:AA12),IF(MONTH(TODAY())=10,SUM(T12:AB12),IF(MONTH(TODAY())=11,SUM(T12:AC12),IF(MONTH(TODAY())=12,SUM(T12:AD12),IF(MONTH(TODAY())=1,SUM(T12:AE12),T12))))))))))) -> 0 | AT12: =SUM(AG12:AR12) -> 0 | AU12: =SUM(AG12:AR12) -> 0 | AW12: =AG12 -> 0 | AX12: =AH12 -> 0 | AY12: =AI12 -> 0 | AZ12: =AJ12 -> 0 | BI12: {=IFERROR(INDEX(AW12:BH12,1,MATCH(2,1/(AW12:BH12<>""))),"")} -> 0 | BJ12: {=IF(BM12 = "", "",IFERROR(INDEX(AW12:BH12,1,MATCH(2,1/(AW12:BH12<>""),1)-1),""))} -> 0 | BK12: =SUM(AW12:BH12) -> 0 | BL12: {=IFERROR(SUM(AW12:INDEX(AW12:BH12, MATCH(2, 1/(AW12:BH12<>""), 1) - 1))/_xlfn.XLOOKUP(F12,Apuração!A:A,Apuração!B:B),0)} -> 0 | BM12: {=IFERROR( INDEX($AW$1:$BH$1, _xlfn.AGGREGATE(14, 6, COLUMN($AW$1:$BH$1)/(AW12:BH12<>""), 2) - COLUMN($AW$1) + 1 ), "")} -> 46082 | BN12: {=IFERROR(INDEX($AW$1:$BH$1,1,MATCH(2,1/(AW12:BH12<>""))),"")} -> 46113 | BO12: =IFERROR(_xlfn.XLOOKUP(F12,Apuração!A:A,Apuração!C:C)/_xlfn.XLOOKUP(F12,Apuração!A:A,Apuração!B:B),0) -> 0.41666667 | BP12: =IFERROR(_xlfn.XLOOKUP(F12,Apuração!A:A,Apuração!D:D)/_xlfn.XLOOKUP(F12,Apuração!A:A,Apuração!B:B),0) -> 0.33333333 | BQ12: =IF(BK12>=BO12,0,_xlfn.XLOOKUP(F12,Apuração!A:A,Apuração!B:B)*(BO12 + (1/_xlfn.XLOOKUP(F12,Apuração!A:A,Apuração!B:B)) - BK12)) -> 6 | BR12: =IF(BQ12=0,0,BQ12*Z12) -> 0 | BS12: =IFERROR((_xlfn.XLOOKUP(F12,Apuração!A:A,Apuração!C:C)+1)/_xlfn.XLOOKUP(F12,Apuração!A:A,Apuração!B:B),0) -> 0.5
A13: POPULAÇÃO | B13: E+ Segurança : parceiros estratégicos | C13: AL | D13: OESTE | E13: {=_xlfn.IFS( F13 = "A partir de Abril", "Aguardando Execução na Distribuidora", A13 = "CAPACITAÇÃO", "Em execução no Corporativo", TRUE, "Em Execução na Distribuidora" )} -> Em Execução na Distribuidora | F13: {=_xlfn.IFS( AG13 <> "", "Jan-Dez/26", AH13 <> "", "Fev-Dez/26", AI13 <> "", "Mar-Dez/26", AJ13 <> "", "Abr-Dez/26", TRUE, "A partir de Junho" )} -> Jan-Dez/26 | G13: Iniciada | H13: P3 | I13: Número de profissionais diretamente impactados | J13: {=_xlfn.LET( _xlpm.actual_value_month, INDEX(T13:AE13, MATCH(DATE(YEAR(TODAY()), MONTH(TODAY()), 1), $T$1:$AE$1, 0)), IF(_xlpm.actual_value_month <> "",_xlpm.actual_value_month & " ações mensais", "") )} | K13: {=_xlfn.LET( _xlpm.sum_month, SUM(T13:AE13), IF(_xlpm.sum_month = 0, "", _xlpm.sum_month & " pessoas impactadas no ano") )} | L13: Número de profissionais diretamente impactados | M13: 1 | N13: Item de controle | O13: Número absoluto | P13: - | Q13: - | R13: - | S13: - | AG13: 259 | AH13: 0 | AI13: 114 | AJ13: 57 | AS13: =IF(MONTH(TODAY())=3,SUM(T13:U13),IF(MONTH(TODAY())=4,SUM(T13:V13),IF(MONTH(TODAY())=5,SUM(T13:W13),IF(MONTH(TODAY())=6,SUM(T13:X13),IF(MONTH(TODAY())=7,SUM(T13:Y13),IF(MONTH(TODAY())=8,SUM(T13:Z13),IF(MONTH(TODAY())=9,SUM(T13:AA13),IF(MONTH(TODAY())=10,SUM(T13:AB13),IF(MONTH(TODAY())=11,SUM(T13:AC13),IF(MONTH(TODAY())=12,SUM(T13:AD13),IF(MONTH(TODAY())=1,SUM(T13:AE13),T13))))))))))) -> 0 | AT13: =SUM(AG13:AR13) -> 430 | AU13: =SUM(AG13:AR13) -> 430 | AW13: =AG13 -> 259 | AX13: =AH13 -> 0 | AY13: =AI13 -> 114 | AZ13: =AJ13 -> 57 | BI13: {=IFERROR(INDEX(AW13:BH13,1,MATCH(2,1/(AW13:BH13<>""))),"")} -> 57 | BJ13: {=IF(BM13 = "", "",IFERROR(INDEX(AW13:BH13,1,MATCH(2,1/(AW13:BH13<>""),1)-1),""))} -> 114 | BK13: =SUM(AW13:BH13) -> 430 | BL13: {=IFERROR(SUM(AW13:INDEX(AW13:BH13, MATCH(2, 1/(AW13:BH13<>""), 1) - 1))/_xlfn.XLOOKUP(F13,Apuração!A:A,Apuração!B:B),0)} -> 31.083333 | BM13: {=IFERROR( INDEX($AW$1:$BH$1, _xlfn.AGGREGATE(14, 6, COLUMN($AW$1:$BH$1)/(AW13:BH13<>""), 2) - COLUMN($AW$1) + 1 ), "")} -> 46082 | BN13: {=IFERROR(INDEX($AW$1:$BH$1,1,MATCH(2,1/(AW13:BH13<>""))),"")} -> 46113 | BO13: =IFERROR(_xlfn.XLOOKUP(F13,Apuração!A:A,Apuração!C:C)/_xlfn.XLOOKUP(F13,Apuração!A:A,Apuração!B:B),0) -> 0.41666667 | BP13: =IFERROR(_xlfn.XLOOKUP(F13,Apuração!A:A,Apuração!D:D)/_xlfn.XLOOKUP(F13,Apuração!A:A,Apuração!B:B),0) -> 0.33333333 | BQ13: =IF(BK13>=BO13,0,_xlfn.XLOOKUP(F13,Apuração!A:A,Apuração!B:B)*(BO13 + (1/_xlfn.XLOOKUP(F13,Apuração!A:A,Apuração!B:B)) - BK13)) -> 0 | BR13: =IF(BQ13=0,0,BQ13*Z13) -> 0 | BS13: =IFERROR((_xlfn.XLOOKUP(F13,Apuração!A:A,Apuração!C:C)+1)/_xlfn.XLOOKUP(F13,Apuração!A:A,Apuração!B:B),0) -> 0.5
A14: POPULAÇÃO | B14: E+ Segurança : vidas salvas | C14: AL | D14: TODAS | E14: Aguardando Execução na Distribuidora | F14: {=_xlfn.IFS( AG14 <> "", "Jan-Dez/26", AH14 <> "", "Fev-Dez/26", AI14 <> "", "Mar-Dez/26", AJ14 <> "", "Abr-Dez/26", TRUE, "A partir de Junho" )} -> A partir de Junho | G14: Não Iniciada | H14: P1 | I14: (N° de colaboradoras = n° de pontos por mês) | J14: {=_xlfn.LET( _xlpm.actual_value_month, INDEX(T14:AE14, MATCH(DATE(YEAR(TODAY()), MONTH(TODAY()), 1), $T$1:$AE$1, 0)), IF(_xlpm.actual_value_month <> "",_xlpm.actual_value_month & " ações mensais", "") )} | K14: {=_xlfn.LET( _xlpm.sum_month, SUM(T14:AE14), IF(_xlpm.sum_month = 0, "", _xlpm.sum_month & " eventos realizados") )} | L14: Percentual de eventos realizados​ | M14: Nível de engajamento dos colaboradores na campanha | N14: Indicador | O14: Percentual | P14: - | Q14: - | R14: Índice de Engajamento em Segurança (IES) | S14: Indicadores de conformidade e engajamento | AS14: =IF(MONTH(TODAY())=3,SUM(T14:U14),IF(MONTH(TODAY())=4,SUM(T14:V14),IF(MONTH(TODAY())=5,SUM(T14:W14),IF(MONTH(TODAY())=6,SUM(T14:X14),IF(MONTH(TODAY())=7,SUM(T14:Y14),IF(MONTH(TODAY())=8,SUM(T14:Z14),IF(MONTH(TODAY())=9,SUM(T14:AA14),IF(MONTH(TODAY())=10,SUM(T14:AB14),IF(MONTH(TODAY())=11,SUM(T14:AC14),IF(MONTH(TODAY())=12,SUM(T14:AD14),IF(MONTH(TODAY())=1,SUM(T14:AE14),T14))))))))))) -> 0 | AT14: =SUM(IF(AW14<1.15,AG14,1.15*T14),IF(AX14<1.15,AH14,1.15*U14),IF(AY14<1.15,AI14,1.15*V14),IF(AZ14<1.15,AJ14,1.15*W14),IF(BA14<1.15,AK14,1.15*X14),IF(BB14<1.15,AL14,1.15*Y14),IF(BC14<1.15,AM14,1.15*Z14),IF(BD14<1.15,AN14,1.15*AA14),IF(BE14<1.15,AO14,1.15*AB14),IF(BF14<1.15,AP14,1.15*AC14),IF(BG14<1.15,AQ14,1.15*AD14),IF(BH14<1.15,AR14,1.15*AE14)) -> 0 | AU14: =SUM(AG14:AR14) -> 0 | AW14: =IFERROR(IF(AG14="",0,AG14/T14),0) -> 0 | AX14: =IFERROR(IF(AH14="",0,AH14/U14),0) -> 0 | AY14: =IFERROR(IF(AI14="",0,AI14/V14),0) -> 0 | AZ14: =IFERROR(IF(AJ14="",0,AJ14/W14),0) -> 0 | BI14: {=IFERROR(INDEX(AW14:BH14,1,MATCH(2,1/(AW14:BH14<>""))),"")} -> 0 | BJ14: {=IF(BM14 = "", "",IFERROR(INDEX(AW14:BH14,1,MATCH(2,1/(AW14:BH14<>""),1)-1),""))} -> 0 | BK14: =IF((IF(AW14>=115%,115%,AW14) + IF(AX14>=115%,115%,AX14) + IF(AY14>=115%,115%,AY14) + (IF(AZ14>=115%,115%,AZ14) + IF(BA14>=115%,115%,BA14) + IF(BB14>=115%,115%,BB14) + IF(BC14>=115%,115%,BC14) + IF(BD14>=115%,115%,BD14) + IF(BE14>=115%,115%,BE14) + IF(BF14>=115%,115%,BF14) + IF(BG14>=115%,115%,BG14) + IF(BH14>=115%,115%,BH14)))/_xlfn.XLOOKUP(F14,Apuração!A:A,Apuração!B:B)>=1.15,1.15,((IF(AZ14>=115%,115%,AZ14) + IF(AX14>=115%,115%,AX14) + IF(AY14>=115%,115%,AY14) + (IF(AW14>=115%,115%,AW14) + IF(BA14>=115%,115%,BA14) + IF(BB14>=115%,115%,BB14) + IF(BC14>=115%,115%,BC14) + IF(BD14>=115%,115%,BD14) + IF(BE14>=115%,115%,BE14) + IF(BF14>=115%,115%,BF14) + IF(BG14>=115%,115%,BG14) + IF(BH14>=115%,115%,BH14)))/_xlfn.XLOOKUP(F14,Apuração!A:A,Apuração!B:B))) -> 0 | BL14: {=IF(SUM(IFERROR(IF(INDEX(AW14:INDEX(AW14:BH14, MATCH(2, 1/(AW14:BH14<>""), 1)-1), ROW(INDIRECT("1:" & MATCH(2, 1/(AW14:BH14<>""), 1)-1))) >= 115%, 115%, INDEX(AW14:INDEX(AW14:BH14, MATCH(2, 1/(AW14:BH14<>""), 1)-1), ROW(INDIRECT("1:" & MATCH(2, 1/(AW14:BH14<>""), 1)-1)))), 0))/_xlfn.XLOOKUP(F14,Apuração!A:A,Apuração!B:B)>=1.15,1.15,SUM(IFERROR(IF(INDEX(AW14:INDEX(AW14:BH14, MATCH(2, 1/(AW14:BH14<>""), 1)-1), ROW(INDIRECT("1:" & MATCH(2, 1/(AW14:BH14<>""), 1)-1))) >= 115%, 115%, INDEX(AW14:INDEX(AW14:BH14, MATCH(2, 1/(AW14:BH14<>""), 1)-1), ROW(INDIRECT("1:" & MATCH(2, 1/(AW14:BH14<>""), 1)-1)))), 0))/_xlfn.XLOOKUP(F14,Apuração!A:A,Apuração!B:B))} -> 0 | BM14: {=IFERROR( INDEX($AW$1:$BH$1, _xlfn.AGGREGATE(14, 6, COLUMN($AW$1:$BH$1)/(AW14:BH14<>""), 2) - COLUMN($AW$1) + 1 ), "")} -> 46082 | BN14: {=IFERROR(INDEX($AW$1:$BH$1,1,MATCH(2,1/(AW14:BH14<>""))),"")} -> 46113 | BO14: =IFERROR(_xlfn.XLOOKUP(F14,Apuração!A:A,Apuração!C:C)/_xlfn.XLOOKUP(F14,Apuração!A:A,Apuração!B:B),0) -> 0 | BP14: =IFERROR(_xlfn.XLOOKUP(F14,Apuração!A:A,Apuração!D:D)/_xlfn.XLOOKUP(F14,Apuração!A:A,Apuração!B:B),0) -> 0 | BQ14: =IF(BK14>=BO14,0,_xlfn.XLOOKUP(F14,Apuração!A:A,Apuração!B:B)*(BO14 + (1/_xlfn.XLOOKUP(F14,Apuração!A:A,Apuração!B:B)) - BK14)) -> 0 | BR14: =IF(BQ14=0,0,BQ14*Z14) -> 0 | BS14: =IFERROR((_xlfn.XLOOKUP(F14,Apuração!A:A,Apuração!C:C)+1)/_xlfn.XLOOKUP(F14,Apuração!A:A,Apuração!B:B),0) -> 0.14285714
A15: POPULAÇÃO | B15: E+ Segurança : vidas salvas | C15: AL | D15: LESTE | E15: Aguardando Execução na Distribuidora | F15: {=_xlfn.IFS( AG15 <> "", "Jan-Dez/26", AH15 <> "", "Fev-Dez/26", AI15 <> "", "Mar-Dez/26", AJ15 <> "", "Abr-Dez/26", TRUE, "A partir de Junho" )} -> A partir de Junho | G15: Não Iniciada | H15: P1 | I15: (N° de colaboradoras = n° de pontos por mês) | J15: {=_xlfn.LET( _xlpm.actual_value_month, INDEX(T15:AE15, MATCH(DATE(YEAR(TODAY()), MONTH(TODAY()), 1), $T$1:$AE$1, 0)), IF(_xlpm.actual_value_month <> "",_xlpm.actual_value_month & " ações mensais", "") )} | K15: {=_xlfn.LET( _xlpm.sum_month, SUM(T15:AE15), IF(_xlpm.sum_month = 0, "", _xlpm.sum_month & " eventos realizados") )} | L15: Percentual de eventos realizados​ | M15: Nível de engajamento dos colaboradores na campanha | N15: Indicador | O15: Percentual | P15: - | Q15: - | R15: Índice de Engajamento em Segurança (IES) | S15: Indicadores de conformidade e engajamento | AS15: =IF(MONTH(TODAY())=3,SUM(T15:U15),IF(MONTH(TODAY())=4,SUM(T15:V15),IF(MONTH(TODAY())=5,SUM(T15:W15),IF(MONTH(TODAY())=6,SUM(T15:X15),IF(MONTH(TODAY())=7,SUM(T15:Y15),IF(MONTH(TODAY())=8,SUM(T15:Z15),IF(MONTH(TODAY())=9,SUM(T15:AA15),IF(MONTH(TODAY())=10,SUM(T15:AB15),IF(MONTH(TODAY())=11,SUM(T15:AC15),IF(MONTH(TODAY())=12,SUM(T15:AD15),IF(MONTH(TODAY())=1,SUM(T15:AE15),T15))))))))))) -> 0 | AT15: =SUM(IF(AW15<1.15,AG15,1.15*T15),IF(AX15<1.15,AH15,1.15*U15),IF(AY15<1.15,AI15,1.15*V15),IF(AZ15<1.15,AJ15,1.15*W15),IF(BA15<1.15,AK15,1.15*X15),IF(BB15<1.15,AL15,1.15*Y15),IF(BC15<1.15,AM15,1.15*Z15),IF(BD15<1.15,AN15,1.15*AA15),IF(BE15<1.15,AO15,1.15*AB15),IF(BF15<1.15,AP15,1.15*AC15),IF(BG15<1.15,AQ15,1.15*AD15),IF(BH15<1.15,AR15,1.15*AE15)) -> 0 | AU15: =SUM(AG15:AR15) -> 0 | AW15: =IFERROR(IF(AG15="",0,AG15/T15),0) -> 0 | AX15: =IFERROR(IF(AH15="",0,AH15/U15),0) -> 0 | AY15: =IFERROR(IF(AI15="",0,AI15/V15),0) -> 0 | AZ15: =IFERROR(IF(AJ15="",0,AJ15/W15),0) -> 0 | BI15: {=IFERROR(INDEX(AW15:BH15,1,MATCH(2,1/(AW15:BH15<>""))),"")} -> 0 | BJ15: {=IF(BM15 = "", "",IFERROR(INDEX(AW15:BH15,1,MATCH(2,1/(AW15:BH15<>""),1)-1),""))} -> 0 | BK15: =IF((IF(AW15>=115%,115%,AW15) + IF(AX15>=115%,115%,AX15) + IF(AY15>=115%,115%,AY15) + (IF(AZ15>=115%,115%,AZ15) + IF(BA15>=115%,115%,BA15) + IF(BB15>=115%,115%,BB15) + IF(BC15>=115%,115%,BC15) + IF(BD15>=115%,115%,BD15) + IF(BE15>=115%,115%,BE15) + IF(BF15>=115%,115%,BF15) + IF(BG15>=115%,115%,BG15) + IF(BH15>=115%,115%,BH15)))/_xlfn.XLOOKUP(F15,Apuração!A:A,Apuração!B:B)>=1.15,1.15,((IF(AZ15>=115%,115%,AZ15) + IF(AX15>=115%,115%,AX15) + IF(AY15>=115%,115%,AY15) + (IF(AW15>=115%,115%,AW15) + IF(BA15>=115%,115%,BA15) + IF(BB15>=115%,115%,BB15) + IF(BC15>=115%,115%,BC15) + IF(BD15>=115%,115%,BD15) + IF(BE15>=115%,115%,BE15) + IF(BF15>=115%,115%,BF15) + IF(BG15>=115%,115%,BG15) + IF(BH15>=115%,115%,BH15)))/_xlfn.XLOOKUP(F15,Apuração!A:A,Apuração!B:B))) -> 0 | BL15: {=IF(SUM(IFERROR(IF(INDEX(AW15:INDEX(AW15:BH15, MATCH(2, 1/(AW15:BH15<>""), 1)-1), ROW(INDIRECT("1:" & MATCH(2, 1/(AW15:BH15<>""), 1)-1))) >= 115%, 115%, INDEX(AW15:INDEX(AW15:BH15, MATCH(2, 1/(AW15:BH15<>""), 1)-1), ROW(INDIRECT("1:" & MATCH(2, 1/(AW15:BH15<>""), 1)-1)))), 0))/_xlfn.XLOOKUP(F15,Apuração!A:A,Apuração!B:B)>=1.15,1.15,SUM(IFERROR(IF(INDEX(AW15:INDEX(AW15:BH15, MATCH(2, 1/(AW15:BH15<>""), 1)-1), ROW(INDIRECT("1:" & MATCH(2, 1/(AW15:BH15<>""), 1)-1))) >= 115%, 115%, INDEX(AW15:INDEX(AW15:BH15, MATCH(2, 1/(AW15:BH15<>""), 1)-1), ROW(INDIRECT("1:" & MATCH(2, 1/(AW15:BH15<>""), 1)-1)))), 0))/_xlfn.XLOOKUP(F15,Apuração!A:A,Apuração!B:B))} -> 0 | BM15: {=IFERROR( INDEX($AW$1:$BH$1, _xlfn.AGGREGATE(14, 6, COLUMN($AW$1:$BH$1)/(AW15:BH15<>""), 2) - COLUMN($AW$1) + 1 ), "")} -> 46082 | BN15: {=IFERROR(INDEX($AW$1:$BH$1,1,MATCH(2,1/(AW15:BH15<>""))),"")} -> 46113 | BO15: =IFERROR(_xlfn.XLOOKUP(F15,Apuração!A:A,Apuração!C:C)/_xlfn.XLOOKUP(F15,Apuração!A:A,Apuração!B:B),0) -> 0 | BP15: =IFERROR(_xlfn.XLOOKUP(F15,Apuração!A:A,Apuração!D:D)/_xlfn.XLOOKUP(F15,Apuração!A:A,Apuração!B:B),0) -> 0 | BQ15: =IF(BK15>=BO15,0,_xlfn.XLOOKUP(F15,Apuração!A:A,Apuração!B:B)*(BO15 + (1/_xlfn.XLOOKUP(F15,Apuração!A:A,Apuração!B:B)) - BK15)) -> 0 | BR15: =IF(BQ15=0,0,BQ15*Z15) -> 0 | BS15: =IFERROR((_xlfn.XLOOKUP(F15,Apuração!A:A,Apuração!C:C)+1)/_xlfn.XLOOKUP(F15,Apuração!A:A,Apuração!B:B),0) -> 0.14285714
A16: POPULAÇÃO | B16: E+ Segurança : vidas salvas | C16: AL | D16: OESTE | E16: Aguardando Execução na Distribuidora | F16: {=_xlfn.IFS( AG16 <> "", "Jan-Dez/26", AH16 <> "", "Fev-Dez/26", AI16 <> "", "Mar-Dez/26", AJ16 <> "", "Abr-Dez/26", TRUE, "A partir de Junho" )} -> A partir de Junho | G16: Não Iniciada | H16: P1 | I16: (N° de colaboradoras = n° de pontos por mês) | J16: {=_xlfn.LET( _xlpm.actual_value_month, INDEX(T16:AE16, MATCH(DATE(YEAR(TODAY()), MONTH(TODAY()), 1), $T$1:$AE$1, 0)), IF(_xlpm.actual_value_month <> "",_xlpm.actual_value_month & " ações mensais", "") )} | K16: {=_xlfn.LET( _xlpm.sum_month, SUM(T16:AE16), IF(_xlpm.sum_month = 0, "", _xlpm.sum_month & " eventos realizados") )} | L16: Percentual de eventos realizados​ | M16: Nível de engajamento dos colaboradores na campanha | N16: Indicador | O16: Percentual | P16: - | Q16: - | R16: Índice de Engajamento em Segurança (IES) | S16: Indicadores de conformidade e engajamento | AS16: =IF(MONTH(TODAY())=3,SUM(T16:U16),IF(MONTH(TODAY())=4,SUM(T16:V16),IF(MONTH(TODAY())=5,SUM(T16:W16),IF(MONTH(TODAY())=6,SUM(T16:X16),IF(MONTH(TODAY())=7,SUM(T16:Y16),IF(MONTH(TODAY())=8,SUM(T16:Z16),IF(MONTH(TODAY())=9,SUM(T16:AA16),IF(MONTH(TODAY())=10,SUM(T16:AB16),IF(MONTH(TODAY())=11,SUM(T16:AC16),IF(MONTH(TODAY())=12,SUM(T16:AD16),IF(MONTH(TODAY())=1,SUM(T16:AE16),T16))))))))))) -> 0 | AT16: =SUM(IF(AW16<1.15,AG16,1.15*T16),IF(AX16<1.15,AH16,1.15*U16),IF(AY16<1.15,AI16,1.15*V16),IF(AZ16<1.15,AJ16,1.15*W16),IF(BA16<1.15,AK16,1.15*X16),IF(BB16<1.15,AL16,1.15*Y16),IF(BC16<1.15,AM16,1.15*Z16),IF(BD16<1.15,AN16,1.15*AA16),IF(BE16<1.15,AO16,1.15*AB16),IF(BF16<1.15,AP16,1.15*AC16),IF(BG16<1.15,AQ16,1.15*AD16),IF(BH16<1.15,AR16,1.15*AE16)) -> 0 | AU16: =SUM(AG16:AR16) -> 0 | AW16: =IFERROR(IF(AG16="",0,AG16/T16),0) -> 0 | AX16: =IFERROR(IF(AH16="",0,AH16/U16),0) -> 0 | AY16: =IFERROR(IF(AI16="",0,AI16/V16),0) -> 0 | AZ16: =IFERROR(IF(AJ16="",0,AJ16/W16),0) -> 0 | BI16: {=IFERROR(INDEX(AW16:BH16,1,MATCH(2,1/(AW16:BH16<>""))),"")} -> 0 | BJ16: {=IF(BM16 = "", "",IFERROR(INDEX(AW16:BH16,1,MATCH(2,1/(AW16:BH16<>""),1)-1),""))} -> 0 | BK16: =IF((IF(AW16>=115%,115%,AW16) + IF(AX16>=115%,115%,AX16) + IF(AY16>=115%,115%,AY16) + (IF(AZ16>=115%,115%,AZ16) + IF(BA16>=115%,115%,BA16) + IF(BB16>=115%,115%,BB16) + IF(BC16>=115%,115%,BC16) + IF(BD16>=115%,115%,BD16) + IF(BE16>=115%,115%,BE16) + IF(BF16>=115%,115%,BF16) + IF(BG16>=115%,115%,BG16) + IF(BH16>=115%,115%,BH16)))/_xlfn.XLOOKUP(F16,Apuração!A:A,Apuração!B:B)>=1.15,1.15,((IF(AZ16>=115%,115%,AZ16) + IF(AX16>=115%,115%,AX16) + IF(AY16>=115%,115%,AY16) + (IF(AW16>=115%,115%,AW16) + IF(BA16>=115%,115%,BA16) + IF(BB16>=115%,115%,BB16) + IF(BC16>=115%,115%,BC16) + IF(BD16>=115%,115%,BD16) + IF(BE16>=115%,115%,BE16) + IF(BF16>=115%,115%,BF16) + IF(BG16>=115%,115%,BG16) + IF(BH16>=115%,115%,BH16)))/_xlfn.XLOOKUP(F16,Apuração!A:A,Apuração!B:B))) -> 0 | BL16: {=IF(SUM(IFERROR(IF(INDEX(AW16:INDEX(AW16:BH16, MATCH(2, 1/(AW16:BH16<>""), 1)-1), ROW(INDIRECT("1:" & MATCH(2, 1/(AW16:BH16<>""), 1)-1))) >= 115%, 115%, INDEX(AW16:INDEX(AW16:BH16, MATCH(2, 1/(AW16:BH16<>""), 1)-1), ROW(INDIRECT("1:" & MATCH(2, 1/(AW16:BH16<>""), 1)-1)))), 0))/_xlfn.XLOOKUP(F16,Apuração!A:A,Apuração!B:B)>=1.15,1.15,SUM(IFERROR(IF(INDEX(AW16:INDEX(AW16:BH16, MATCH(2, 1/(AW16:BH16<>""), 1)-1), ROW(INDIRECT("1:" & MATCH(2, 1/(AW16:BH16<>""), 1)-1))) >= 115%, 115%, INDEX(AW16:INDEX(AW16:BH16, MATCH(2, 1/(AW16:BH16<>""), 1)-1), ROW(INDIRECT("1:" & MATCH(2, 1/(AW16:BH16<>""), 1)-1)))), 0))/_xlfn.XLOOKUP(F16,Apuração!A:A,Apuração!B:B))} -> 0 | BM16: {=IFERROR( INDEX($AW$1:$BH$1, _xlfn.AGGREGATE(14, 6, COLUMN($AW$1:$BH$1)/(AW16:BH16<>""), 2) - COLUMN($AW$1) + 1 ), "")} -> 46082 | BN16: {=IFERROR(INDEX($AW$1:$BH$1,1,MATCH(2,1/(AW16:BH16<>""))),"")} -> 46113 | BO16: =IFERROR(_xlfn.XLOOKUP(F16,Apuração!A:A,Apuração!C:C)/_xlfn.XLOOKUP(F16,Apuração!A:A,Apuração!B:B),0) -> 0 | BP16: =IFERROR(_xlfn.XLOOKUP(F16,Apuração!A:A,Apuração!D:D)/_xlfn.XLOOKUP(F16,Apuração!A:A,Apuração!B:B),0) -> 0 | BQ16: =IF(BK16>=BO16,0,_xlfn.XLOOKUP(F16,Apuração!A:A,Apuração!B:B)*(BO16 + (1/_xlfn.XLOOKUP(F16,Apuração!A:A,Apuração!B:B)) - BK16)) -> 0 | BR16: =IF(BQ16=0,0,BQ16*Z16) -> 0 | BS16: =IFERROR((_xlfn.XLOOKUP(F16,Apuração!A:A,Apuração!C:C)+1)/_xlfn.XLOOKUP(F16,Apuração!A:A,Apuração!B:B),0) -> 0.14285714
A17: POPULAÇÃO | B17: E+ Segurança : vidas salvas | C17: AL | D17: TODAS | E17: Aguardando Execução na Distribuidora | F17: {=_xlfn.IFS( AG17 <> "", "Jan-Dez/26", AH17 <> "", "Fev-Dez/26", AI17 <> "", "Mar-Dez/26", AJ17 <> "", "Abr-Dez/26", TRUE, "A partir de Junho" )} -> A partir de Junho | G17: Não Iniciada | H17: P1 | I17: (N° notificações de risco tratadas / N° total de notificações de risco apontadas) * 100 | J17: {=_xlfn.LET( _xlpm.actual_value_month, INDEX(T17:AE17, MATCH(DATE(YEAR(TODAY()), MONTH(TODAY()), 1), $T$1:$AE$1, 0)), IF(_xlpm.actual_value_month <> "",_xlpm.actual_value_month & " ações mensais", "") )} | K17: {=_xlfn.LET( _xlpm.sum_month, SUM(T17:AE17), IF(_xlpm.sum_month = 0, "", _xlpm.sum_month & " notificações.") )} | L17: Notificações sanadas | M17: 1 | N17: Item de controle | O17: Percentual | P17: - | Q17: - | R17: - | S17: - | AS17: =IF(MONTH(TODAY())=3,SUM(T17:U17),IF(MONTH(TODAY())=4,SUM(T17:V17),IF(MONTH(TODAY())=5,SUM(T17:W17),IF(MONTH(TODAY())=6,SUM(T17:X17),IF(MONTH(TODAY())=7,SUM(T17:Y17),IF(MONTH(TODAY())=8,SUM(T17:Z17),IF(MONTH(TODAY())=9,SUM(T17:AA17),IF(MONTH(TODAY())=10,SUM(T17:AB17),IF(MONTH(TODAY())=11,SUM(T17:AC17),IF(MONTH(TODAY())=12,SUM(T17:AD17),IF(MONTH(TODAY())=1,SUM(T17:AE17),T17))))))))))) -> 0 | AT17: =SUM(AG17:AR17) -> 0 | AU17: =SUM(AG17:AR17) -> 0 | AW17: =AG17 -> 0 | AX17: =AH17 -> 0 | AY17: =AI17 -> 0 | AZ17: =AJ17 -> 0 | BI17: {=IFERROR(INDEX(AW17:BH17,1,MATCH(2,1/(AW17:BH17<>""))),"")} -> 0 | BJ17: {=IF(BM17 = "", "",IFERROR(INDEX(AW17:BH17,1,MATCH(2,1/(AW17:BH17<>""),1)-1),""))} -> 0 | BK17: =SUM(AW17:BH17) -> 0 | BL17: {=IFERROR(SUM(AW17:INDEX(AW17:BH17, MATCH(2, 1/(AW17:BH17<>""), 1) - 1))/_xlfn.XLOOKUP(F17,Apuração!A:A,Apuração!B:B),0)} -> 0 | BM17: {=IFERROR( INDEX($AW$1:$BH$1, _xlfn.AGGREGATE(14, 6, COLUMN($AW$1:$BH$1)/(AW17:BH17<>""), 2) - COLUMN($AW$1) + 1 ), "")} -> 46082 | BN17: {=IFERROR(INDEX($AW$1:$BH$1,1,MATCH(2,1/(AW17:BH17<>""))),"")} -> 46113 | BO17: =IFERROR(_xlfn.XLOOKUP(F17,Apuração!A:A,Apuração!C:C)/_xlfn.XLOOKUP(F17,Apuração!A:A,Apuração!B:B),0) -> 0 | BP17: =IFERROR(_xlfn.XLOOKUP(F17,Apuração!A:A,Apuração!D:D)/_xlfn.XLOOKUP(F17,Apuração!A:A,Apuração!B:B),0) -> 0 | BQ17: =IF(BK17>=BO17,0,_xlfn.XLOOKUP(F17,Apuração!A:A,Apuração!B:B)*(BO17 + (1/_xlfn.XLOOKUP(F17,Apuração!A:A,Apuração!B:B)) - BK17)) -> 0 | BR17: =IF(BQ17=0,0,BQ17*Z17) -> 0 | BS17: =IFERROR((_xlfn.XLOOKUP(F17,Apuração!A:A,Apuração!C:C)+1)/_xlfn.XLOOKUP(F17,Apuração!A:A,Apuração!B:B),0) -> 0.14285714
